Workbook

Sheet README
A1: Numbersmith | Cap Table and Dilution Calculator
A2: Model SAFEs, a priced round, option pool top-up, dilution scenarios, and an exit waterfall, all with open Excel formulas.
A4: Purpose
A5: This workbook helps a founder plan a priced fundraising round: how outstanding SAFEs and convertible notes convert, how the option pool gets topped up, what price per share the round sets, how much every holder ends up owning, and what everyone would walk away with at an exit. It ships pre-filled with a realistic two-founder seed round so you can see it work before you replace the numbers with your own.
A7: How to use this workbook (6 steps)
B8: 1. Current Cap Table tab: list your existing holders (founders, employees, advisors, option pool) with share counts and vesting notes.
B9: 2. SAFEs and Notes tab: list any outstanding SAFEs or convertible notes with amount, type, cap, discount, and (for notes) interest and term.
B10: 3. Priced Round tab: enter the pre-money valuation, up to three new investors, and the target post-money option pool percent.
B11: 4. Priced Round tab: review the computed price per share, SAFE and note conversion, and the full post-round cap table by holder and by class.
B12: 5. Dilution Scenarios tab: compare three raise scenarios side by side and see founder ownership after a hypothetical Series A.
B13: 6. Exit Waterfall tab: enter an exit value and liquidation preference terms to see the payout by holder and per share.
A15: Color legend
B16: Blue text on light yellow fill | C16: An input cell. Type your own numbers here.
B17: Black text, no fill | C17: A formula. It recalculates automatically; do not overwrite it.
B18: Green text, no fill | C18: A link that pulls a value from another tab.
A20: Glossary
B21: Pre-money valuation | C21: What the company is agreed to be worth immediately before the new round's cash comes in.
B22: Post-money valuation | C22: Pre-money valuation plus the new money raised; what the company is worth right after the round closes.
B23: Option pool shuffle | C23: The common practice of increasing the option pool before a priced round so the new pool dilutes existing shareholders rather than the new investor, effectively lowering the price new investors pay.
B24: SAFE | C24: A Simple Agreement for Future Equity. Not a loan or equity today; it converts into shares in a later priced round, usually based on a valuation cap and/or a discount.
B25: Valuation cap | C25: The maximum company valuation used to price a SAFE's or note's conversion, protecting early money from paying a later, higher round price.
B26: Discount | C26: A percent reduction applied to the priced round's per-share price, giving SAFE or note holders a cheaper conversion price than new investors pay.
B27: Pro rata | C27: An investor's right (or a holder's share) calculated in proportion to their existing ownership percent.
B28: Liquidation preference | C28: A right that lets preferred investors get paid before common holders at an exit, usually a multiple of what they invested (1x is typical).
B29: Fully diluted | C29: The total share count if every option, warrant, SAFE, and note were exercised or converted into common stock.
B30: Price per share | C30: The dollar value assigned to one share in a round, used to convert an investment amount into a share count.
A32: Tabs in this workbook
B33: Current Cap Table | C33: Up to 12 existing holders and the fully diluted share count before this round.
B34: SAFEs and Notes | C34: Up to 6 SAFEs or convertible notes and their conversion terms.
B35: Priced Round | C35: Inputs for the new round; computes price per share, conversions, and the full post-round cap table.
B36: Dilution Scenarios | C36: Three raise scenarios compared side by side, plus a hypothetical Series A and a chart.
B37: Exit Waterfall | C37: Models an exit and shows payout by holder, with a chart across three exit values.
A40: This is a planning tool for founders, not legal, tax, or investment advice. Real SAFE and note conversion terms, option pool mechanics, and liquidation waterfalls vary by the actual documents signed; always have counsel review your term sheet and cap table before you close a round.
B43: Built by Numbersmith with AI assistance. Formulas are open; nothing is hidden or locked.
B45: For education and planning only, not financial advice.

Sheet Current Cap Table
A1: Current Cap Table
A2: Every existing holder, fully diluted, before this round. Enter shares for up to 12 holders below.
A4: # | B4: Holder | C4: Class | D4: Shares | E4: Vesting / Notes | F4: % Fully Diluted
A5: 1 | B5: Founder A | C5: Founder | D5: 4500000 | E5: 4-yr vest, 1-yr cliff; fully vested | F5: =IF($D$18=0,0,D5/$D$18) -> 0.5
A6: 2 | B6: Founder B | C6: Founder | D6: 3500000 | E6: 4-yr vest, 1-yr cliff; fully vested | F6: =IF($D$18=0,0,D6/$D$18) -> 0.38888889
A7: 3 | B7: Option Pool (Unallocated) | C7: Option Pool | D7: 1000000 | E7: Reserved for future employee and advisor grants | F7: =IF($D$18=0,0,D7/$D$18) -> 0.11111111
A8: 4 | F8: =IF($D$18=0,0,D8/$D$18) -> 0
A9: 5 | F9: =IF($D$18=0,0,D9/$D$18) -> 0
A10: 6 | F10: =IF($D$18=0,0,D10/$D$18) -> 0
A11: 7 | F11: =IF($D$18=0,0,D11/$D$18) -> 0
A12: 8 | F12: =IF($D$18=0,0,D12/$D$18) -> 0
A13: 9 | F13: =IF($D$18=0,0,D13/$D$18) -> 0
A14: 10 | F14: =IF($D$18=0,0,D14/$D$18) -> 0
A15: 11 | F15: =IF($D$18=0,0,D15/$D$18) -> 0
A16: 12 | F16: =IF($D$18=0,0,D16/$D$18) -> 0
B18: Total | D18: =SUM(D5:D16) -> 9000000 | F18: =SUM(F5:F16) -> 1
B20: Existing Option Pool (shares) | D20: =SUMIF(C5:C16,"Option Pool",D5:D16) -> 1000000
B21: Founders + Employees + Advisors (non-pool shares) | D21: =D18-D20 -> 8000000
B22: Founders Only (shares) | D22: =SUMIF(C5:C16,"Founder",D5:D16) -> 8000000
A24: These four reference rows feed every other tab in this workbook. Keep the Class column limited to Founder, Employee, Advisor, or Option Pool so the totals above stay accurate.

Sheet SAFEs and Notes
A1: SAFEs and Notes
A2: Up to 6 outstanding SAFEs or convertible notes. Conversion into shares is computed on the Priced Round tab.
A4: # | B4: Holder / Label | C4: Instrument Type | D4: Amount Invested | E4: Valuation Cap (0 = uncapped) | F4: Discount % | G4: Interest %/yr (notes only) | H4: Term (months) (notes only) | I4: Accrued Amount at Conversion
A5: 1 | B5: SAFE Investor 1 | C5: Post-money SAFE | D5: 500000 | E5: 8000000 | F5: 0 | G5: 0 | H5: 0 | I5: =IF(D5=0,0,IF(C5="Convertible Note",D5*(1+G5*H5/12),D5)) -> 500000
A6: 2 | B6: SAFE Investor 2 | C6: Pre-money SAFE | D6: 250000 | E6: 6000000 | F6: 0.2 | G6: 0 | H6: 0 | I6: =IF(D6=0,0,IF(C6="Convertible Note",D6*(1+G6*H6/12),D6)) -> 250000
A7: 3 | I7: =IF(D7=0,0,IF(C7="Convertible Note",D7*(1+G7*H7/12),D7)) -> 0
A8: 4 | I8: =IF(D8=0,0,IF(C8="Convertible Note",D8*(1+G8*H8/12),D8)) -> 0
A9: 5 | I9: =IF(D9=0,0,IF(C9="Convertible Note",D9*(1+G9*H9/12),D9)) -> 0
A10: 6 | I10: =IF(D10=0,0,IF(C10="Convertible Note",D10*(1+G10*H10/12),D10)) -> 0
B12: Total | D12: =SUM(D5:D10) -> 750000 | I12: =SUM(I5:I10) -> 750000
A14: Accrued Amount adds simple interest for convertible notes only (Amount x (1 + rate x months / 12)); SAFEs never accrue interest. On the Priced Round tab, each instrument converts at the better (lower) of its cap price and its discount price, except a post-money SAFE, whose ownership percent is Amount / Cap by definition and is solved directly for a share count.

Sheet Priced Round
A1: Priced Round
A2: New round terms, SAFE and note conversion, the option pool top-up, price per share, and the full post-round cap table.
A4: Inputs
B5: Pre-Money Valuation | D5: 12000000
B6: Target Post-Money Option Pool % | D6: 0.1
B7: Option Pool Topped Up Pre-Money? | D7: Yes
B9: New Investors (up to 3) | C9: Name | D9: Amount Invested
B10: Investor 1 | C10: Seed Lead | D10: 3000000
B11: Investor 2 | D11: 0
B12: Investor 3 | D12: 0
B13: Total New Money Raised | D13: =SUM(D10:D12) -> 3000000
A15: Baseline (from Current Cap Table)
B16: Pre-Round Fully Diluted Shares (Founders + Pool) | D16: ='Current Cap Table'!$D$18 -> 9000000
B17: of which: Existing Option Pool (shares) | D17: ='Current Cap Table'!$D$20 -> 1000000
B18: of which: Founders + Employees + Advisors (shares) | D18: ='Current Cap Table'!$D$21 -> 8000000
A20: SAFE and Note Conversion
A21: Cap price = Valuation Cap / Pre-Round Fully Diluted Shares above. Discount price approximates the round price as Pre-Money Valuation / Pre-Round Fully Diluted Shares, then applies the discount; each instrument converts at whichever price is lower. A post-money SAFE instead converts at Amount / Cap of ownership, solved directly for a share count.
A22: # | B22: Holder | C22: Type | D22: Accrued Amount | E22: Cap | F22: Discount % | G22: Cap Price /Sh | H22: Discount Price /Sh | I22: Conversion Price /Sh | J22: Conversion Shares
A23: 1 | B23: =IF('SAFEs and Notes'!B5="","",'SAFEs and Notes'!B5) -> SAFE Investor 1 | C23: =IF('SAFEs and Notes'!C5="","",'SAFEs and Notes'!C5) -> Post-money SAFE | D23: ='SAFEs and Notes'!I5 -> 500000 | E23: ='SAFEs and Notes'!E5 -> 8000000 | F23: ='SAFEs and Notes'!F5 -> 0 | G23: =IF(AND(E23>0,C23<>"Post-money SAFE"),E23/$D$16,"") | H23: =IF(AND(F23>0,C23<>"Post-money SAFE"),($D$5/$D$16)*(1-F23),"") | I23: =IF(D23=0,"",IF(C23="Post-money SAFE","",IF(AND(G23<>"",H23<>""),MIN(G23,H23),IF(G23<>"",G23,IF(H23<>"",H23,""))))) | J23: =IF(D23=0,0,IF(C23="Post-money SAFE",(D23/E23)*$D$16/(1-(D23/E23)),IF(I23="",0,D23/I23))) -> 600000
A24: 2 | B24: =IF('SAFEs and Notes'!B6="","",'SAFEs and Notes'!B6) -> SAFE Investor 2 | C24: =IF('SAFEs and Notes'!C6="","",'SAFEs and Notes'!C6) -> Pre-money SAFE | D24: ='SAFEs and Notes'!I6 -> 250000 | E24: ='SAFEs and Notes'!E6 -> 6000000 | F24: ='SAFEs and Notes'!F6 -> 0.2 | G24: =IF(AND(E24>0,C24<>"Post-money SAFE"),E24/$D$16,"") -> 0.66666667 | H24: =IF(AND(F24>0,C24<>"Post-money SAFE"),($D$5/$D$16)*(1-F24),"") -> 1.0666667 | I24: =IF(D24=0,"",IF(C24="Post-money SAFE","",IF(AND(G24<>"",H24<>""),MIN(G24,H24),IF(G24<>"",G24,IF(H24<>"",H24,""))))) -> 0.66666667 | J24: =IF(D24=0,0,IF(C24="Post-money SAFE",(D24/E24)*$D$16/(1-(D24/E24)),IF(I24="",0,D24/I24))) -> 375000
A25: 3 | B25: =IF('SAFEs and Notes'!B7="","",'SAFEs and Notes'!B7) | C25: =IF('SAFEs and Notes'!C7="","",'SAFEs and Notes'!C7) | D25: ='SAFEs and Notes'!I7 -> 0 | E25: ='SAFEs and Notes'!E7 -> 0 | F25: ='SAFEs and Notes'!F7 -> 0 | G25: =IF(AND(E25>0,C25<>"Post-money SAFE"),E25/$D$16,"") | H25: =IF(AND(F25>0,C25<>"Post-money SAFE"),($D$5/$D$16)*(1-F25),"") | I25: =IF(D25=0,"",IF(C25="Post-money SAFE","",IF(AND(G25<>"",H25<>""),MIN(G25,H25),IF(G25<>"",G25,IF(H25<>"",H25,""))))) | J25: =IF(D25=0,0,IF(C25="Post-money SAFE",(D25/E25)*$D$16/(1-(D25/E25)),IF(I25="",0,D25/I25))) -> 0
A26: 4 | B26: =IF('SAFEs and Notes'!B8="","",'SAFEs and Notes'!B8) | C26: =IF('SAFEs and Notes'!C8="","",'SAFEs and Notes'!C8) | D26: ='SAFEs and Notes'!I8 -> 0 | E26: ='SAFEs and Notes'!E8 -> 0 | F26: ='SAFEs and Notes'!F8 -> 0 | G26: =IF(AND(E26>0,C26<>"Post-money SAFE"),E26/$D$16,"") | H26: =IF(AND(F26>0,C26<>"Post-money SAFE"),($D$5/$D$16)*(1-F26),"") | I26: =IF(D26=0,"",IF(C26="Post-money SAFE","",IF(AND(G26<>"",H26<>""),MIN(G26,H26),IF(G26<>"",G26,IF(H26<>"",H26,""))))) | J26: =IF(D26=0,0,IF(C26="Post-money SAFE",(D26/E26)*$D$16/(1-(D26/E26)),IF(I26="",0,D26/I26))) -> 0
A27: 5 | B27: =IF('SAFEs and Notes'!B9="","",'SAFEs and Notes'!B9) | C27: =IF('SAFEs and Notes'!C9="","",'SAFEs and Notes'!C9) | D27: ='SAFEs and Notes'!I9 -> 0 | E27: ='SAFEs and Notes'!E9 -> 0 | F27: ='SAFEs and Notes'!F9 -> 0 | G27: =IF(AND(E27>0,C27<>"Post-money SAFE"),E27/$D$16,"") | H27: =IF(AND(F27>0,C27<>"Post-money SAFE"),($D$5/$D$16)*(1-F27),"") | I27: =IF(D27=0,"",IF(C27="Post-money SAFE","",IF(AND(G27<>"",H27<>""),MIN(G27,H27),IF(G27<>"",G27,IF(H27<>"",H27,""))))) | J27: =IF(D27=0,0,IF(C27="Post-money SAFE",(D27/E27)*$D$16/(1-(D27/E27)),IF(I27="",0,D27/I27))) -> 0
A28: 6 | B28: =IF('SAFEs and Notes'!B10="","",'SAFEs and Notes'!B10) | C28: =IF('SAFEs and Notes'!C10="","",'SAFEs and Notes'!C10) | D28: ='SAFEs and Notes'!I10 -> 0 | E28: ='SAFEs and Notes'!E10 -> 0 | F28: ='SAFEs and Notes'!F10 -> 0 | G28: =IF(AND(E28>0,C28<>"Post-money SAFE"),E28/$D$16,"") | H28: =IF(AND(F28>0,C28<>"Post-money SAFE"),($D$5/$D$16)*(1-F28),"") | I28: =IF(D28=0,"",IF(C28="Post-money SAFE","",IF(AND(G28<>"",H28<>""),MIN(G28,H28),IF(G28<>"",G28,IF(H28<>"",H28,""))))) | J28: =IF(D28=0,0,IF(C28="Post-money SAFE",(D28/E28)*$D$16/(1-(D28/E28)),IF(I28="",0,D28/I28))) -> 0
B29: Total SAFE / Note Conversion Shares | J29: =SUM(J23:J28) -> 975000
A31: Option Pool Shuffle and Price Per Share
A32: The option pool top-up is created pre-money when the toggle above is Yes, so it dilutes founders, the existing pool, and converting SAFEs and notes, the same way new investor cash does not. If the toggle is No, the top-up is instead sized so the pool reaches its target percent of the fully diluted post-money total without changing the price new investors pay.
B33: Post-Money Valuation | D33: =D5+D13 -> 15000000
B34: Pool Sizing Factor (K) | D34: =D6*(D33/D5) -> 0.125
B35: Pre-Pool Fully Diluted Shares (Founders + Pool + Converted SAFEs) | D35: =D16+J29 -> 9975000
B36: New Option Pool Shares (Top-Up) | D36: =MAX((D34*D35-D17)/(1-IF(D7="Yes",D34,D6)),0) -> 282142.86
B37: Price Per Share (this round) | D37: =IF(D7="Yes",D5/(D35+D36),D5/D35) -> 1.1699164
B38: New Investor Shares (total) | D38: =D13/D37 -> 2564285.7
B39: Post-Money Fully Diluted Shares (Total) | D39: =D35+D36+D38 -> 12821429
B40: Check: Price Per Share x Post-Money Shares = Post-Money Valuation | D40: =D37*D39 -> 15000000
B41: Check OK? | D41: =IF(ROUND(D40-D33,2)=0,"OK","ERROR") -> OK
A43: Post-Round Capitalization Table
A44: # | B44: Holder | C44: Class | D44: Shares | E44: % of Post-Money Fully Diluted
A45: 1 | B45: =IF('Current Cap Table'!B5="","",'Current Cap Table'!B5) -> Founder A | C45: =IF('Current Cap Table'!C5="","",'Current Cap Table'!C5) -> Founder | D45: ='Current Cap Table'!D5 -> 4500000 | E45: =IF($D$39=0,0,D45/$D$39) -> 0.35097493
A46: 2 | B46: =IF('Current Cap Table'!B6="","",'Current Cap Table'!B6) -> Founder B | C46: =IF('Current Cap Table'!C6="","",'Current Cap Table'!C6) -> Founder | D46: ='Current Cap Table'!D6 -> 3500000 | E46: =IF($D$39=0,0,D46/$D$39) -> 0.2729805
...

Sheet Dilution Scenarios
A1: Dilution Scenarios
A2: Compare three raise scenarios side by side, then see founders' combined ownership after a hypothetical Series A.
A4: Scenario Inputs
C5: Scenario A | D5: Scenario B | E5: Scenario C
B6: Scenario Name | C6: Conservative | D6: Base Case | E6: Aggressive
B7: Pre-Money Valuation | C7: 10000000 | D7: 12000000 | E7: 15000000
B8: New Money Raised | C8: 2500000 | D8: 3000000 | E8: 4000000
B9: Target Post-Money Option Pool % | C9: 0.1 | D9: 0.1 | E9: 0.1
B10: Pool Topped Up Pre-Money? | C10: Yes | D10: Yes | E10: Yes
A12: Reference Prices by Scenario
B13: Baseline Fully Diluted Shares (existing) | C13: ='Current Cap Table'!$D$18 -> 9000000
B14: Reference Price per Share (Pre-Money / Baseline) | C14: =C7/$C$13 -> 1.1111111 | D14: =D7/$C$13 -> 1.3333333 | E14: =E7/$C$13 -> 1.6666667
A16: SAFE and Note Conversion Shares by Scenario
A17: # | B17: Holder | C17: Type | D17: Cap | E17: Discount % | F17: Accrued Amt | G17: Cap Price/Sh | H17: Scenario A Shares | I17: Scenario B Shares | J17: Scenario C Shares
A18: 1 | B18: =IF('SAFEs and Notes'!B5="","",'SAFEs and Notes'!B5) -> SAFE Investor 1 | C18: =IF('SAFEs and Notes'!C5="","",'SAFEs and Notes'!C5) -> Post-money SAFE | D18: ='SAFEs and Notes'!E5 -> 8000000 | E18: ='SAFEs and Notes'!F5 -> 0 | F18: ='SAFEs and Notes'!I5 -> 500000 | G18: =IF(D18>0,D18/$C$13,"") -> 0.88888889 | H18: =IF(F18=0,0,IF(C18="Post-money SAFE",(F18/D18)*$C$13/(1-(F18/D18)),IF(AND(G18<>"",E18>0),F18/MIN(G18,$C$14*(1-E18)),IF(G18<>"",F18/G18,IF(E18>0,F18/($C$14*(1-E18)),0))))) -> 600000 | I18: =IF(F18=0,0,IF(C18="Post-money SAFE",(F18/D18)*$C$13/(1-(F18/D18)),IF(AND(G18<>"",E18>0),F18/MIN(G18,$D$14*(1-E18)),IF(G18<>"",F18/G18,IF(E18>0,F18/($D$14*(1-E18)),0))))) -> 600000 | J18: =IF(F18=0,0,IF(C18="Post-money SAFE",(F18/D18)*$C$13/(1-(F18/D18)),IF(AND(G18<>"",E18>0),F18/MIN(G18,$E$14*(1-E18)),IF(G18<>"",F18/G18,IF(E18>0,F18/($E$14*(1-E18)),0))))) -> 600000
A19: 2 | B19: =IF('SAFEs and Notes'!B6="","",'SAFEs and Notes'!B6) -> SAFE Investor 2 | C19: =IF('SAFEs and Notes'!C6="","",'SAFEs and Notes'!C6) -> Pre-money SAFE | D19: ='SAFEs and Notes'!E6 -> 6000000 | E19: ='SAFEs and Notes'!F6 -> 0.2 | F19: ='SAFEs and Notes'!I6 -> 250000 | G19: =IF(D19>0,D19/$C$13,"") -> 0.66666667 | H19: =IF(F19=0,0,IF(C19="Post-money SAFE",(F19/D19)*$C$13/(1-(F19/D19)),IF(AND(G19<>"",E19>0),F19/MIN(G19,$C$14*(1-E19)),IF(G19<>"",F19/G19,IF(E19>0,F19/($C$14*(1-E19)),0))))) -> 375000 | I19: =IF(F19=0,0,IF(C19="Post-money SAFE",(F19/D19)*$C$13/(1-(F19/D19)),IF(AND(G19<>"",E19>0),F19/MIN(G19,$D$14*(1-E19)),IF(G19<>"",F19/G19,IF(E19>0,F19/($D$14*(1-E19)),0))))) -> 375000 | J19: =IF(F19=0,0,IF(C19="Post-money SAFE",(F19/D19)*$C$13/(1-(F19/D19)),IF(AND(G19<>"",E19>0),F19/MIN(G19,$E$14*(1-E19)),IF(G19<>"",F19/G19,IF(E19>0,F19/($E$14*(1-E19)),0))))) -> 375000
A20: 3 | B20: =IF('SAFEs and Notes'!B7="","",'SAFEs and Notes'!B7) | C20: =IF('SAFEs and Notes'!C7="","",'SAFEs and Notes'!C7) | D20: ='SAFEs and Notes'!E7 -> 0 | E20: ='SAFEs and Notes'!F7 -> 0 | F20: ='SAFEs and Notes'!I7 -> 0 | G20: =IF(D20>0,D20/$C$13,"") | H20: =IF(F20=0,0,IF(C20="Post-money SAFE",(F20/D20)*$C$13/(1-(F20/D20)),IF(AND(G20<>"",E20>0),F20/MIN(G20,$C$14*(1-E20)),IF(G20<>"",F20/G20,IF(E20>0,F20/($C$14*(1-E20)),0))))) -> 0 | I20: =IF(F20=0,0,IF(C20="Post-money SAFE",(F20/D20)*$C$13/(1-(F20/D20)),IF(AND(G20<>"",E20>0),F20/MIN(G20,$D$14*(1-E20)),IF(G20<>"",F20/G20,IF(E20>0,F20/($D$14*(1-E20)),0))))) -> 0 | J20: =IF(F20=0,0,IF(C20="Post-money SAFE",(F20/D20)*$C$13/(1-(F20/D20)),IF(AND(G20<>"",E20>0),F20/MIN(G20,$E$14*(1-E20)),IF(G20<>"",F20/G20,IF(E20>0,F20/($E$14*(1-E20)),0))))) -> 0
A21: 4 | B21: =IF('SAFEs and Notes'!B8="","",'SAFEs and Notes'!B8) | C21: =IF('SAFEs and Notes'!C8="","",'SAFEs and Notes'!C8) | D21: ='SAFEs and Notes'!E8 -> 0 | E21: ='SAFEs and Notes'!F8 -> 0 | F21: ='SAFEs and Notes'!I8 -> 0 | G21: =IF(D21>0,D21/$C$13,"") | H21: =IF(F21=0,0,IF(C21="Post-money SAFE",(F21/D21)*$C$13/(1-(F21/D21)),IF(AND(G21<>"",E21>0),F21/MIN(G21,$C$14*(1-E21)),IF(G21<>"",F21/G21,IF(E21>0,F21/($C$14*(1-E21)),0))))) -> 0 | I21: =IF(F21=0,0,IF(C21="Post-money SAFE",(F21/D21)*$C$13/(1-(F21/D21)),IF(AND(G21<>"",E21>0),F21/MIN(G21,$D$14*(1-E21)),IF(G21<>"",F21/G21,IF(E21>0,F21/($D$14*(1-E21)),0))))) -> 0 | J21: =IF(F21=0,0,IF(C21="Post-money SAFE",(F21/D21)*$C$13/(1-(F21/D21)),IF(AND(G21<>"",E21>0),F21/MIN(G21,$E$14*(1-E21)),IF(G21<>"",F21/G21,IF(E21>0,F21/($E$14*(1-E21)),0))))) -> 0
A22: 5 | B22: =IF('SAFEs and Notes'!B9="","",'SAFEs and Notes'!B9) | C22: =IF('SAFEs and Notes'!C9="","",'SAFEs and Notes'!C9) | D22: ='SAFEs and Notes'!E9 -> 0 | E22: ='SAFEs and Notes'!F9 -> 0 | F22: ='SAFEs and Notes'!I9 -> 0 | G22: =IF(D22>0,D22/$C$13,"") | H22: =IF(F22=0,0,IF(C22="Post-money SAFE",(F22/D22)*$C$13/(1-(F22/D22)),IF(AND(G22<>"",E22>0),F22/MIN(G22,$C$14*(1-E22)),IF(G22<>"",F22/G22,IF(E22>0,F22/($C$14*(1-E22)),0))))) -> 0 | I22: =IF(F22=0,0,IF(C22="Post-money SAFE",(F22/D22)*$C$13/(1-(F22/D22)),IF(AND(G22<>"",E22>0),F22/MIN(G22,$D$14*(1-E22)),IF(G22<>"",F22/G22,IF(E22>0,F22/($D$14*(1-E22)),0))))) -> 0 | J22: =IF(F22=0,0,IF(C22="Post-money SAFE",(F22/D22)*$C$13/(1-(F22/D22)),IF(AND(G22<>"",E22>0),F22/MIN(G22,$E$14*(1-E22)),IF(G22<>"",F22/G22,IF(E22>0,F22/($E$14*(1-E22)),0))))) -> 0
A23: 6 | B23: =IF('SAFEs and Notes'!B10="","",'SAFEs and Notes'!B10) | C23: =IF('SAFEs and Notes'!C10="","",'SAFEs and Notes'!C10) | D23: ='SAFEs and Notes'!E10 -> 0 | E23: ='SAFEs and Notes'!F10 -> 0 | F23: ='SAFEs and Notes'!I10 -> 0 | G23: =IF(D23>0,D23/$C$13,"") | H23: =IF(F23=0,0,IF(C23="Post-money SAFE",(F23/D23)*$C$13/(1-(F23/D23)),IF(AND(G23<>"",E23>0),F23/MIN(G23,$C$14*(1-E23)),IF(G23<>"",F23/G23,IF(E23>0,F23/($C$14*(1-E23)),0))))) -> 0 | I23: =IF(F23=0,0,IF(C23="Post-money SAFE",(F23/D23)*$C$13/(1-(F23/D23)),IF(AND(G23<>"",E23>0),F23/MIN(G23,$D$14*(1-E23)),IF(G23<>"",F23/G23,IF(E23>0,F23/($D$14*(1-E23)),0))))) -> 0 | J23: =IF(F23=0,0,IF(C23="Post-money SAFE",(F23/D23)*$C$13/(1-(F23/D23)),IF(AND(G23<>"",E23>0),F23/MIN(G23,$E$14*(1-E23)),IF(G23<>"",F23/G23,IF(E23>0,F23/($E$14*(1-E23)),0))))) -> 0
B24: Total SAFE / Note Conversion Shares | H24: =SUM(H18:H23) -> 975000 | I24: =SUM(I18:I23) -> 975000 | J24: =SUM(J18:J23) -> 975000
A26: Scenario Results
C27: =C6 -> Conservative | D27: =D6 -> Base Case | E27: =E6 -> Aggressive
B28: Post-Money Valuation | C28: =C7+C8 -> 12500000 | D28: =D7+D8 -> 15000000 | E28: =E7+E8 -> 19000000
B29: Pool Sizing Factor (K) | C29: =C9*(C28/C7) -> 0.125 | D29: =D9*(D28/D7) -> 0.125 | E29: =E9*(E28/E7) -> 0.12666667
B30: Pre-Pool Fully Diluted Shares (Founders+Pool+SAFEs) | C30: =$C$13+H24 -> 9975000 | D30: =$C$13+I24 -> 9975000 | E30: =$C$13+J24 -> 9975000
B31: New Option Pool Shares | C31: =MAX((C29*C30-'Current Cap Table'!$D$20)/(1-IF(C10="Yes",C29,C9)),0) -> 282142.86 | D31: =MAX((D29*D30-'Current Cap Table'!$D$20)/(1-IF(D10="Yes",D29,D9)),0) -> 282142.86 | E31: =MAX((E29*E30-'Current Cap Table'!$D$20)/(1-IF(E10="Yes",E29,E9)),0) -> 301717.56
B32: Price Per Share | C32: =IF(C10="Yes",C7/(C30+C31),C7/C30) -> 0.97493036 | D32: =IF(D10="Yes",D7/(D30+D31),D7/D30) -> 1.1699164 | E32: =IF(E10="Yes",E7/(E30+E31),E7/E30) -> 1.45961
B33: Post-Money Fully Diluted Shares (Total) | C33: =C30+C31+C8/C32 -> 12821429 | D33: =D30+D31+D8/D32 -> 12821429 | E33: =E30+E31+E8/E32 -> 13017176
B34: Founders Combined Shares (constant) | C34: ='Current Cap Table'!$D$22 -> 8000000 | D34: ='Current Cap Table'!$D$22 -> 8000000 | E34: ='Current Cap Table'!$D$22 -> 8000000
B35: Founders Combined % After This Round | C35: =C34/C33 -> 0.62395543 | D35: =D34/D33 -> 0.62395543 | E35: =E34/E33 -> 0.61457264
A37: Hypothetical Next Round (Series A)
A38: Series A is modeled as simple pro-rata dilution applied uniformly on top of each scenario's post-seed cap table (one shared Series A assumption for all three columns, no additional option pool top-up), for a quick side-by-side look. For a precise build, copy each scenario's terms onto the Priced Round tab.
B39: Series A Pre-Money Valuation | D39: 40000000
B40: Series A Amount Raised | D40: 8000000
B41: Series A New-Investor % (simple pro-rata) | D41: =D40/(D39+D40) -> 0.16666667
B42: Founders Combined % After Series A | C42: =C35*(1-$D$41) -> 0.51996286 | D42: =D35*(1-$D$41) -> 0.51996286 | E42: =E35*(1-$D$41) -> 0.51214387
A44: Founder Ownership Chart Data
A45: Scenario | B45: Founders % After Seed | C45: Founders % After Series A
A46: =C6 -> Conservative | B46: =C35 -> 0.62395543 | C46: =C42 -> 0.51996286
...

Sheet Exit Waterfall
A1: Exit Waterfall
A2: Model an exit and see the payout by holder class, with a 1x non-participating liquidation preference by default for the priced-round investors.
A4: Exit Inputs
B5: Exit Value (Main Scenario) | D5: 20000000
B6: Liquidation Preference Multiple (priced-round investors) | D6: 1
B7: Preferred Participating? (double-dip) | D7: No
A9: Reference (from Priced Round and Current Cap Table)
B10: Total New Money Raised (priced-round investors) | D10: ='Priced Round'!$D$13 -> 3000000
B11: Priced-Round Investor Shares (total) | D11: ='Priced Round'!$D$38 -> 2564285.7
B12: Post-Money Fully Diluted Shares (Total) | D12: ='Priced Round'!$D$39 -> 12821429
B13: Founders Combined Shares | D13: ='Current Cap Table'!$D$22 -> 8000000
B14: Employees + Advisors Combined Shares | D14: ='Current Cap Table'!$D$21-'Current Cap Table'!$D$22 -> 0
B15: Option Pool Combined Shares (existing + top-up) | D15: ='Current Cap Table'!$D$20+'Priced Round'!$D$36 -> 1282142.9
B16: Converted SAFE / Note Shares (combined) | D16: ='Priced Round'!$J$29 -> 975000
A18: Waterfall -- Main Exit Scenario
B19: Liquidation Preference Amount | D19: =D10*D6 -> 3000000
B20: Preferred As-Converted Value (if converted to common) | D20: =D5*(D11/D12) -> 4000000
B21: Preferred Takes Preference or Converts? | D21: =IF(D7="Yes","Participates (preference + pro rata)",IF(D20>D19,"Converts to common","Takes preference")) -> Converts to common
B22: Preferred Payout (priced-round investors) | D22: =IF(D7="Yes",MIN(D19,D5)+(D5-MIN(D19,D5))*(D11/D12),IF(D20>D19,D5*(D11/D12),MIN(D19,D5))) -> 4000000
B23: Value Available to Common-Class Holders | D23: =D5-D22 -> 16000000
B24: Per-Share Value, Common-Class Holders | D24: =IF((D12-D11)=0,0,D23/(D12-D11)) -> 1.5598886
B25: Per-Share Value, Preferred (Priced-Round) Investors | D25: =IF(D11=0,0,D22/D11) -> 1.5598886
A27: Payout by Holder -- Main Exit Scenario
B28: Holder Class | C28: Shares | D28: Payout ($) | E28: Payout per Share ($)
B29: Founders (combined) | C29: =D13 -> 8000000 | D29: =C29*$D$24 -> 12479109 | E29: =$D$24 -> 1.5598886
B30: Employees + Advisors (combined) | C30: =D14 -> 0 | D30: =C30*$D$24 -> 0 | E30: =$D$24 -> 1.5598886
B31: Option Pool (combined) | C31: =D15 -> 1282142.9 | D31: =C31*$D$24 -> 2000000 | E31: =$D$24 -> 1.5598886
B32: Converted SAFEs/Notes (combined) | C32: =D16 -> 975000 | D32: =C32*$D$24 -> 1520891.4 | E32: =$D$24 -> 1.5598886
B33: Priced-Round Investors (combined, preferred) | C33: =D11 -> 2564285.7 | D33: =$D$22 -> 4000000 | E33: =$D$25 -> 1.5598886
B34: Total | C34: =SUM(C29:C33) -> 12821429 | D34: =SUM(D29:D33) -> 20000000
B35: Check: Total Payout = Exit Value? | D35: =IF(ROUND(D34-$D$5,2)=0,"OK","ERROR") -> OK
A37: Exit Value Sensitivity (for chart)
B38: Exit Value Scenario 1 (down) | D38: 2000000
B39: Exit Value Scenario 2 (moderate) | D39: 20000000
B40: Exit Value Scenario 3 (strong) | D40: 75000000
A42: Payout by Class at Each Exit Value
B43: Holder Class | C43: @ Scenario 1 | D43: @ Scenario 2 | E43: @ Scenario 3
B44: Preferred Payout (priced-round investors) | C44: =IF($D$7="Yes",MIN($D$19,$D$38)+($D$38-MIN($D$19,$D$38))*($D$11/$D$12),IF($D$38*($D$11/$D$12)>$D$19,$D$38*($D$11/$D$12),MIN($D$19,$D$38))) -> 2000000 | D44: =IF($D$7="Yes",MIN($D$19,$D$39)+($D$39-MIN($D$19,$D$39))*($D$11/$D$12),IF($D$39*($D$11/$D$12)>$D$19,$D$39*($D$11/$D$12),MIN($D$19,$D$39))) -> 4000000 | E44: =IF($D$7="Yes",MIN($D$19,$D$40)+($D$40-MIN($D$19,$D$40))*($D$11/$D$12),IF($D$40*($D$11/$D$12)>$D$19,$D$40*($D$11/$D$12),MIN($D$19,$D$40))) -> 15000000
B45: Per-Share Value, Common-Class Holders | C45: =IF(($D$12-$D$11)=0,0,($D$38-C44)/($D$12-$D$11)) -> 0 | D45: =IF(($D$12-$D$11)=0,0,($D$39-D44)/($D$12-$D$11)) -> 1.5598886 | E45: =IF(($D$12-$D$11)=0,0,($D$40-E44)/($D$12-$D$11)) -> 5.8495822
B47: Founders (combined) | C47: =$D$13*C45 -> 0 | D47: =$D$13*D45 -> 12479109 | E47: =$D$13*E45 -> 46796657
...
