Workbook

Sheet README
B1: Numbersmith - Startup Financial Model
B2: 3-statement, driver-based model for pre-seed / seed founders
A4: WHAT THIS MODEL DOES
B5: This workbook builds a full 3-statement financial model (Income Statement, Balance Sheet, Cash Flow) for an early-stage startup from a small set of operating drivers: customers, price, churn, headcount, and operating spend. It projects 36 months in detail and rolls that detail up into a 5-year annual view, with Years 4-5 extrapolated from the Year-3 run-rate. Every output is a formula that traces back to the Assumptions tab, so changing one input recalculates the entire model, including the balance sheet, which balances to the penny in every year.
A7: HOW TO USE IT
B8: Start on the Assumptions tab and replace the sample numbers (a two-stream B2B SaaS company with a $2.4M raise) with your own. The Monthly tab shows the full 36-month build; the Annual tab summarizes it into a 5-year, investor-ready set of statements. Unit Economics reports CAC, LTV, the LTV:CAC ratio, and payback period; Runway & Raise reports months of runway, the month cash would run out (if any), and a raise-sizing calculator with a 5x5 growth-vs-churn sensitivity grid on Year-3 revenue. Charts gives you three ready-made visuals for a deck or a data room. Nothing is locked, so you can extend any tab, add rows, or change formulas directly.
A10: COLOR LEGEND
B11: Blue font - Input cell. The only cells you should type over.
B12: Black font - Formula that calculates using cells on the same sheet.
B13: Green font - Formula that links to another sheet.
A15: QUICK START (6 STEPS)
B16: 1. Open the Assumptions tab. Update General, Revenue Streams 1-2, and the Cash Minimum Threshold.
B17: 2. Fill in your Headcount Plan (role, start month, fully-loaded monthly cost, count) - add or remove rows as needed, keeping the Monthly tab's SUMPRODUCT ranges pointed at the full table.
B18: 3. Set Opex, Capex & Depreciation, and Working Capital (DSO / DPO / deferred revenue days).
B19: 4. Enter your Financing plan: equity raise amount and month, and an optional loan (amount, start month, rate, term). Set the Year 4-5 growth assumptions.
B20: 5. Review the Monthly and Annual tabs. Confirm the Balance Check row on Annual reads 0.00 in every year and that the Monthly cash flag row stays clear of BELOW MIN.
B21: 6. Check Unit Economics and Runway & Raise, then pull the charts on the Charts tab into your deck or data room.
A23: Built by Numbersmith with AI assistance. Formulas are open; nothing is hidden or locked.
A25: For education and planning only, not financial advice.

Sheet Assumptions
A1: Assumptions
A2: All inputs for the model live on this sheet only. Blue font = input cell. Figures below are illustrative starting values for a sample B2B SaaS pre-seed company; replace with your own numbers.
A3: GENERAL
A4: Model Start Month | B4: 46023
A5: Corporate Tax Rate | B5: 0.21
A6: Cash Minimum Warning Threshold | B6: 50000
A7: Starting Cash Balance (pre-raise) | B7: 0
A9: REVENUE - STREAM 1 (Core Platform Subscription)
A10: Starting Customers (Month 1 beginning balance) | B10: 0
A11: Month 1 New Customers | B11: 20
A12: Monthly Growth in New Customers % | B12: 0.06
A13: Monthly Churn % | B13: 0.04
A14: Price per Customer / Month | B14: 500
A15: COGS % of Revenue | B15: 0.18
A17: REVENUE - STREAM 2 (Add-on Services)
A18: Starting Customers (Month 1 beginning balance) | B18: 0
A19: Month 1 New Customers | B19: 8
A20: Monthly Growth in New Customers % | B20: 0.05
A21: Monthly Churn % | B21: 0.055
A22: Price per Customer / Month | B22: 180
A23: COGS % of Revenue | B23: 0.25
A25: HEADCOUNT PLAN
A26: Role | B26: Start Month (#) | C26: Fully-Loaded Cost / Mo | D26: Count
A27: Founder / CEO | B27: 1 | C27: 13000 | D27: 1
A28: Founder / CTO | B28: 1 | C28: 13000 | D28: 1
A29: Engineer | B29: 2 | C29: 11500 | D29: 1
A30: Sales Lead | B30: 4 | C30: 9500 | D30: 1
A31: Customer Success | B31: 6 | C31: 7000 | D31: 1
A32: Engineer | B32: 9 | C32: 11500 | D32: 1
A33: Marketing Manager | B33: 11 | C33: 8500 | D33: 1
A34: Engineer | B34: 15 | C34: 11500 | D34: 1
A35: Sales Rep | B35: 18 | C35: 8000 | D35: 1
A36: Finance / Ops | B36: 21 | C36: 8500 | D36: 1
A38: OPERATING EXPENSES
A39: Rent ($ / month) | B39: 4000
A40: Software & Tools ($ / month) | B40: 2500
A41: Marketing (% of Revenue) | B41: 0.25
A42: Other G&A ($ / month) | B42: 3000
A44: CAPEX & DEPRECIATION
A45: Monthly Capex ($) | B45: 3000
...

Sheet Monthly
A1: Monthly Model - 36 Months
A3: Month # | B3: 1 | C3: =B3+1 -> 2 | D3: =C3+1 -> 3 | E3: =D3+1 -> 4 | F3: =E3+1 -> 5 | G3: =F3+1 -> 6 | H3: =G3+1 -> 7 | I3: =H3+1 -> 8 | J3: =I3+1 -> 9 | ... AK3: =AJ3+1 -> 36
A4: Calendar Month | B4: =Assumptions!$B$4 -> 46023 | C4: =EDATE(B4,1) -> 46054 | D4: =EDATE(C4,1) -> 46082 | E4: =EDATE(D4,1) -> 46113 | F4: =EDATE(E4,1) -> 46143 | G4: =EDATE(F4,1) -> 46174 | H4: =EDATE(G4,1) -> 46204 | I4: =EDATE(H4,1) -> 46235 | J4: =EDATE(I4,1) -> 46266 | ... AK4: =EDATE(AJ4,1) -> 47088
A6: CUSTOMERS
A7: Stream 1 - New Customers | B7: =Assumptions!$B$11 -> 20 | C7: =B7*(1+Assumptions!$B$12) -> 21.2 | D7: =C7*(1+Assumptions!$B$12) -> 22.472 | E7: =D7*(1+Assumptions!$B$12) -> 23.82032 | F7: =E7*(1+Assumptions!$B$12) -> 25.249539 | G7: =F7*(1+Assumptions!$B$12) -> 26.764512 | H7: =G7*(1+Assumptions!$B$12) -> 28.370382 | I7: =H7*(1+Assumptions!$B$12) -> 30.072605 | J7: =I7*(1+Assumptions!$B$12) -> 31.876961 | ... AK7: =AJ7*(1+Assumptions!$B$12) -> 153.72174
A8: Stream 1 - Ending Customers | B8: =Assumptions!$B$10*(1-Assumptions!$B$13)+B7 -> 20 | C8: =B8*(1-Assumptions!$B$13)+C7 -> 40.4 | D8: =C8*(1-Assumptions!$B$13)+D7 -> 61.256 | E8: =D8*(1-Assumptions!$B$13)+E7 -> 82.62608 | F8: =E8*(1-Assumptions!$B$13)+F7 -> 104.57058 | G8: =F8*(1-Assumptions!$B$13)+G7 -> 127.15226 | H8: =G8*(1-Assumptions!$B$13)+H7 -> 150.43656 | I8: =H8*(1-Assumptions!$B$13)+I7 -> 174.4917 | J8: =I8*(1-Assumptions!$B$13)+J7 -> 199.38899 | ... AK8: =AJ8*(1-Assumptions!$B$13)+AK7 -> 1583.4465
A9: Stream 2 - New Customers | B9: =Assumptions!$B$19 -> 8 | C9: =B9*(1+Assumptions!$B$20) -> 8.4 | D9: =C9*(1+Assumptions!$B$20) -> 8.82 | E9: =D9*(1+Assumptions!$B$20) -> 9.261 | F9: =E9*(1+Assumptions!$B$20) -> 9.72405 | G9: =F9*(1+Assumptions!$B$20) -> 10.210252 | H9: =G9*(1+Assumptions!$B$20) -> 10.720765 | I9: =H9*(1+Assumptions!$B$20) -> 11.256803 | J9: =I9*(1+Assumptions!$B$20) -> 11.819644 | ... AK9: =AJ9*(1+Assumptions!$B$20) -> 44.128123
A10: Stream 2 - Ending Customers | B10: =Assumptions!$B$18*(1-Assumptions!$B$21)+B9 -> 8 | C10: =B10*(1-Assumptions!$B$21)+C9 -> 15.96 | D10: =C10*(1-Assumptions!$B$21)+D9 -> 23.9022 | E10: =D10*(1-Assumptions!$B$21)+E9 -> 31.848579 | F10: =E10*(1-Assumptions!$B$21)+F9 -> 39.820957 | G10: =F10*(1-Assumptions!$B$21)+G9 -> 47.841057 | H10: =G10*(1-Assumptions!$B$21)+H9 -> 55.930564 | I10: =H10*(1-Assumptions!$B$21)+I9 -> 64.111186 | J10: =I10*(1-Assumptions!$B$21)+J9 -> 72.404715 | ... AK10: =AJ10*(1-Assumptions!$B$21)+AK9 -> 431.33987
A12: REVENUE
A13: Stream 1 Revenue | B13: =B8*Assumptions!$B$14 -> 10000 | C13: =C8*Assumptions!$B$14 -> 20200 | D13: =D8*Assumptions!$B$14 -> 30628 | E13: =E8*Assumptions!$B$14 -> 41313.04 | F13: =F8*Assumptions!$B$14 -> 52285.288 | G13: =G8*Assumptions!$B$14 -> 63576.132 | H13: =H8*Assumptions!$B$14 -> 75218.278 | I13: =I8*Assumptions!$B$14 -> 87245.85 | ... AK13: =AK8*Assumptions!$B$14 -> 791723.26
A14: Stream 2 Revenue | B14: =B10*Assumptions!$B$22 -> 1440 | C14: =C10*Assumptions!$B$22 -> 2872.8 | D14: =D10*Assumptions!$B$22 -> 4302.396 | E14: =E10*Assumptions!$B$22 -> 5732.7442 | F14: =F10*Assumptions!$B$22 -> 7167.7723 | G14: =G10*Assumptions!$B$22 -> 8611.3903 | H14: =H10*Assumptions!$B$22 -> 10067.502 | I14: =I10*Assumptions!$B$22 -> 11540.014 | ... AK14: =AK10*Assumptions!$B$22 -> 77641.177
A15: Total Revenue | B15: =B13+B14 -> 11440 | C15: =C13+C14 -> 23072.8 | D15: =D13+D14 -> 34930.396 | E15: =E13+E14 -> 47045.784 | F15: =F13+F14 -> 59453.06 | G15: =G13+G14 -> 72187.523 | H15: =H13+H14 -> 85285.78 | I15: =I13+I14 -> 98785.863 | ... AK15: =AK13+AK14 -> 869364.44
A17: COGS & GROSS PROFIT
A18: Stream 1 COGS | B18: =B13*Assumptions!$B$15 -> 1800 | C18: =C13*Assumptions!$B$15 -> 3636 | D18: =D13*Assumptions!$B$15 -> 5513.04 | E18: =E13*Assumptions!$B$15 -> 7436.3472 | F18: =F13*Assumptions!$B$15 -> 9411.3518 | G18: =G13*Assumptions!$B$15 -> 11443.704 | H18: =H13*Assumptions!$B$15 -> 13539.29 | I18: =I13*Assumptions!$B$15 -> 15704.253 | ... AK18: =AK13*Assumptions!$B$15 -> 142510.19
A19: Stream 2 COGS | B19: =B14*Assumptions!$B$23 -> 360 | C19: =C14*Assumptions!$B$23 -> 718.2 | D19: =D14*Assumptions!$B$23 -> 1075.599 | E19: =E14*Assumptions!$B$23 -> 1433.1861 | F19: =F14*Assumptions!$B$23 -> 1791.9431 | G19: =G14*Assumptions!$B$23 -> 2152.8476 | H19: =H14*Assumptions!$B$23 -> 2516.8754 | I19: =I14*Assumptions!$B$23 -> 2885.0034 | ... AK19: =AK14*Assumptions!$B$23 -> 19410.294
A20: Total COGS | B20: =B18+B19 -> 2160 | C20: =C18+C19 -> 4354.2 | D20: =D18+D19 -> 6588.639 | E20: =E18+E19 -> 8869.5333 | F20: =F18+F19 -> 11203.295 | G20: =G18+G19 -> 13596.551 | H20: =H18+H19 -> 16056.165 | I20: =I18+I19 -> 18589.256 | ... AK20: =AK18+AK19 -> 161920.48
A21: Gross Profit | B21: =B15-B20 -> 9280 | C21: =C15-C20 -> 18718.6 | D21: =D15-D20 -> 28341.757 | E21: =E15-E20 -> 38176.251 | F21: =F15-F20 -> 48249.765 | G21: =G15-G20 -> 58590.971 | H21: =H15-H20 -> 69229.614 | I21: =I15-I20 -> 80196.607 | ... AK21: =AK15-AK20 -> 707443.96
A22: Gross Margin % | B22: =IFERROR(B21/B15,0) -> 0.81118881 | C22: =IFERROR(C21/C15,0) -> 0.81128428 | D22: =IFERROR(D21/D15,0) -> 0.81137806 | E22: =IFERROR(E21/E15,0) -> 0.81147018 | F22: =IFERROR(F21/F15,0) -> 0.81156067 | G22: =IFERROR(G21/G15,0) -> 0.81164956 | H22: =IFERROR(H21/H15,0) -> 0.8117369 | I22: =IFERROR(I21/I15,0) -> 0.81182271 | ... AK22: =IFERROR(AK21/AK15,0) -> 0.81374844
A24: HEADCOUNT & OPERATING EXPENSES
A25: Headcount Count | B25: =SUMPRODUCT((Assumptions!$B$27:$B$36<=B$3)*Assumptions!$D$27:$D$36) -> 2 | C25: =SUMPRODUCT((Assumptions!$B$27:$B$36<=C$3)*Assumptions!$D$27:$D$36) -> 3 | D25: =SUMPRODUCT((Assumptions!$B$27:$B$36<=D$3)*Assumptions!$D$27:$D$36) -> 3 | E25: =SUMPRODUCT((Assumptions!$B$27:$B$36<=E$3)*Assumptions!$D$27:$D$36) -> 4 | F25: =SUMPRODUCT((Assumptions!$B$27:$B$36<=F$3)*Assumptions!$D$27:$D$36) -> 4 | G25: =SUMPRODUCT((Assumptions!$B$27:$B$36<=G$3)*Assumptions!$D$27:$D$36) -> 5 | H25: =SUMPRODUCT((Assumptions!$B$27:$B$36<=H$3)*Assumptions!$D$27:$D$36) -> 5 | I25: =SUMPRODUCT((Assumptions!$B$27:$B$36<=I$3)*Assumptions!$D$27:$D$36) -> 5 | ... AK25: =SUMPRODUCT((Assumptions!$B$27:$B$36<=AK$3)*Assumptions!$D$27:$D$36) -> 10
A26: Headcount Cost | B26: =SUMPRODUCT((Assumptions!$B$27:$B$36<=B$3)*Assumptions!$C$27:$C$36*Assumptions!$D$27:$D$36) -> 26000 | C26: =SUMPRODUCT((Assumptions!$B$27:$B$36<=C$3)*Assumptions!$C$27:$C$36*Assumptions!$D$27:$D$36) -> 37500 | D26: =SUMPRODUCT((Assumptions!$B$27:$B$36<=D$3)*Assumptions!$C$27:$C$36*Assumptions!$D$27:$D$36) -> 37500 | E26: =SUMPRODUCT((Assumptions!$B$27:$B$36<=E$3)*Assumptions!$C$27:$C$36*Assumptions!$D$27:$D$36) -> 47000 | F26: =SUMPRODUCT((Assumptions!$B$27:$B$36<=F$3)*Assumptions!$C$27:$C$36*Assumptions!$D$27:$D$36) -> 47000 | G26: =SUMPRODUCT((Assumptions!$B$27:$B$36<=G$3)*Assumptions!$C$27:$C$36*Assumptions!$D$27:$D$36) -> 54000 | H26: =SUMPRODUCT((Assumptions!$B$27:$B$36<=H$3)*Assumptions!$C$27:$C$36*Assumptions!$D$27:$D$36) -> 54000 | I26: =SUMPRODUCT((Assumptions!$B$27:$B$36<=I$3)*Assumptions!$C$27:$C$36*Assumptions!$D$27:$D$36) -> 54000 | ... AK26: =SUMPRODUCT((Assumptions!$B$27:$B$36<=AK$3)*Assumptions!$C$27:$C$36*Assumptions!$D$27:$D$36) -> 102000
A27: Rent | B27: =Assumptions!$B$39 -> 4000 | C27: =Assumptions!$B$39 -> 4000 | D27: =Assumptions!$B$39 -> 4000 | E27: =Assumptions!$B$39 -> 4000 | F27: =Assumptions!$B$39 -> 4000 | G27: =Assumptions!$B$39 -> 4000 | H27: =Assumptions!$B$39 -> 4000 | I27: =Assumptions!$B$39 -> 4000 | ... AK27: =Assumptions!$B$39 -> 4000
A28: Software & Tools | B28: =Assumptions!$B$40 -> 2500 | C28: =Assumptions!$B$40 -> 2500 | D28: =Assumptions!$B$40 -> 2500 | E28: =Assumptions!$B$40 -> 2500 | F28: =Assumptions!$B$40 -> 2500 | G28: =Assumptions!$B$40 -> 2500 | H28: =Assumptions!$B$40 -> 2500 | I28: =Assumptions!$B$40 -> 2500 | ... AK28: =Assumptions!$B$40 -> 2500
A29: Marketing (% of Revenue) | B29: =B15*Assumptions!$B$41 -> 2860 | C29: =C15*Assumptions!$B$41 -> 5768.2 | D29: =D15*Assumptions!$B$41 -> 8732.599 | E29: =E15*Assumptions!$B$41 -> 11761.446 | F29: =F15*Assumptions!$B$41 -> 14863.265 | G29: =G15*Assumptions!$B$41 -> 18046.881 | H29: =H15*Assumptions!$B$41 -> 21321.445 | I29: =I15*Assumptions!$B$41 -> 24696.466 | ... AK29: =AK15*Assumptions!$B$41 -> 217341.11
A30: Other G&A | B30: =Assumptions!$B$42 -> 3000 | C30: =Assumptions!$B$42 -> 3000 | D30: =Assumptions!$B$42 -> 3000 | E30: =Assumptions!$B$42 -> 3000 | F30: =Assumptions!$B$42 -> 3000 | G30: =Assumptions!$B$42 -> 3000 | H30: =Assumptions!$B$42 -> 3000 | I30: =Assumptions!$B$42 -> 3000 | ... AK30: =Assumptions!$B$42 -> 3000
A31: Total Operating Expenses | B31: =SUM(B26:B30) -> 38360 | C31: =SUM(C26:C30) -> 52768.2 | D31: =SUM(D26:D30) -> 55732.599 | E31: =SUM(E26:E30) -> 68261.446 | F31: =SUM(F26:F30) -> 71363.265 | G31: =SUM(G26:G30) -> 81546.881 | H31: =SUM(H26:H30) -> 84821.445 | I31: =SUM(I26:I30) -> 88196.466 | ... AK31: =SUM(AK26:AK30) -> 328841.11
A33: EBITDA TO NET INCOME
A34: EBITDA | B34: =B21-B31 -> -29080 | C34: =C21-C31 -> -34049.6 | D34: =D21-D31 -> -27390.842 | E34: =E21-E31 -> -30085.195 | F34: =F21-F31 -> -23113.5 | G34: =G21-G31 -> -22955.909 | H34: =H21-H31 -> -15591.831 | I34: =I21-I31 -> -7999.859 | ... AK34: =AK21-AK31 -> 378602.85
A35: Capex | B35: =Assumptions!$B$45 -> 3000 | C35: =Assumptions!$B$45 -> 3000 | D35: =Assumptions!$B$45 -> 3000 | E35: =Assumptions!$B$45 -> 3000 | F35: =Assumptions!$B$45 -> 3000 | G35: =Assumptions!$B$45 -> 3000 | H35: =Assumptions!$B$45 -> 3000 | I35: =Assumptions!$B$45 -> 3000 | ... AK35: =Assumptions!$B$45 -> 3000
A36: PP&E, Gross (cumulative) | B36: =B35 -> 3000 | C36: =B36+C35 -> 6000 | D36: =C36+D35 -> 9000 | E36: =D36+E35 -> 12000 | F36: =E36+F35 -> 15000 | G36: =F36+G35 -> 18000 | H36: =G36+H35 -> 21000 | I36: =H36+I35 -> 24000 | J36: =I36+J35 -> 27000 | ... AK36: =AJ36+AK35 -> 108000
A37: Depreciation & Amortization | B37: =B36/Assumptions!$B$46 -> 62.5 | C37: =C36/Assumptions!$B$46 -> 125 | D37: =D36/Assumptions!$B$46 -> 187.5 | E37: =E36/Assumptions!$B$46 -> 250 | F37: =F36/Assumptions!$B$46 -> 312.5 | G37: =G36/Assumptions!$B$46 -> 375 | H37: =H36/Assumptions!$B$46 -> 437.5 | I37: =I36/Assumptions!$B$46 -> 500 | ... AK37: =AK36/Assumptions!$B$46 -> 2250
A38: Accumulated Depreciation | B38: =B37 -> 62.5 | C38: =B38+C37 -> 187.5 | D38: =C38+D37 -> 375 | E38: =D38+E37 -> 625 | F38: =E38+F37 -> 937.5 | G38: =F38+G37 -> 1312.5 | H38: =G38+H37 -> 1750 | I38: =H38+I37 -> 2250 | J38: =I38+J37 -> 2812.5 | ... AK38: =AJ38+AK37 -> 41625
A39: PP&E, Net | B39: =B36-B38 -> 2937.5 | C39: =C36-C38 -> 5812.5 | D39: =D36-D38 -> 8625 | E39: =E36-E38 -> 11375 | F39: =F36-F38 -> 14062.5 | G39: =G36-G38 -> 16687.5 | H39: =H36-H38 -> 19250 | I39: =I36-I38 -> 21750 | ... AK39: =AK36-AK38 -> 66375
A40: EBIT | B40: =B34-B37 -> -29142.5 | C40: =C34-C37 -> -34174.6 | D40: =D34-D37 -> -27578.342 | E40: =E34-E37 -> -30335.195 | F40: =F34-F37 -> -23426 | G40: =G34-G37 -> -23330.909 | H40: =H34-H37 -> -16029.331 | I40: =I34-I37 -> -8499.859 | ... AK40: =AK34-AK37 -> 376352.85
A41: Debt Balance, Beginning | B41: 0 | C41: =B44 -> 0 | D41: =C44 -> 0 | E41: =D44 -> 0 | F41: =E44 -> 0 | G41: =F44 -> 0 | H41: =G44 -> 0 | I41: =H44 -> 0 | J41: =I44 -> 0 | ... AK41: =AJ44 -> 8333.3333
A42: Interest Expense | B42: =B41*(Assumptions!$B$58/12) -> 0 | C42: =C41*(Assumptions!$B$58/12) -> 0 | D42: =D41*(Assumptions!$B$58/12) -> 0 | E42: =E41*(Assumptions!$B$58/12) -> 0 | F42: =F41*(Assumptions!$B$58/12) -> 0 | G42: =G41*(Assumptions!$B$58/12) -> 0 | H42: =H41*(Assumptions!$B$58/12) -> 0 | I42: =I41*(Assumptions!$B$58/12) -> 0 | ... AK42: =AK41*(Assumptions!$B$58/12) -> 62.5
A43: Debt Principal Payment | B43: =IF(AND(B$3>=Assumptions!$B$57,B$3<Assumptions!$B$57+Assumptions!$B$59),Assumptions!$B$56/Assumptions!$B$59,0) -> 0 | C43: =IF(AND(C$3>=Assumptions!$B$57,C$3<Assumptions!$B$57+Assumptions!$B$59),Assumptions!$B$56/Assumptions!$B$59,0) -> 0 | D43: =IF(AND(D$3>=Assumptions!$B$57,D$3<Assumptions!$B$57+Assumptions!$B$59),Assumptions!$B$56/Assumptions!$B$59,0) -> 0 | E43: =IF(AND(E$3>=Assumptions!$B$57,E$3<Assumptions!$B$57+Assumptions!$B$59),Assumptions!$B$56/Assumptions!$B$59,0) -> 0 | F43: =IF(AND(F$3>=Assumptions!$B$57,F$3<Assumptions!$B$57+Assumptions!$B$59),Assumptions!$B$56/Assumptions!$B$59,0) -> 0 | G43: =IF(AND(G$3>=Assumptions!$B$57,G$3<Assumptions!$B$57+Assumptions!$B$59),Assumptions!$B$56/Assumptions!$B$59,0) -> 0 | H43: =IF(AND(H$3>=Assumptions!$B$57,H$3<Assumptions!$B$57+Assumptions!$B$59),Assumptions!$B$56/Assumptions!$B$59,0) -> 0 | I43: =IF(AND(I$3>=Assumptions!$B$57,I$3<Assumptions!$B$57+Assumptions!$B$59),Assumptions!$B$56/Assumptions!$B$59,0) -> 0 | ... AK43: =IF(AND(AK$3>=Assumptions!$B$57,AK$3<Assumptions!$B$57+Assumptions!$B$59),Assumptions!$B$56/Assumptions!$B$59,0) -> 8333.3333
A44: Debt Balance, Ending | B44: =B41+IF(B$3=Assumptions!$B$57,Assumptions!$B$56,0)-B43 -> 0 | C44: =C41+IF(C$3=Assumptions!$B$57,Assumptions!$B$56,0)-C43 -> 0 | D44: =D41+IF(D$3=Assumptions!$B$57,Assumptions!$B$56,0)-D43 -> 0 | E44: =E41+IF(E$3=Assumptions!$B$57,Assumptions!$B$56,0)-E43 -> 0 | F44: =F41+IF(F$3=Assumptions!$B$57,Assumptions!$B$56,0)-F43 -> 0 | G44: =G41+IF(G$3=Assumptions!$B$57,Assumptions!$B$56,0)-G43 -> 0 | H44: =H41+IF(H$3=Assumptions!$B$57,Assumptions!$B$56,0)-H43 -> 0 | I44: =I41+IF(I$3=Assumptions!$B$57,Assumptions!$B$56,0)-I43 -> 0 | ... AK44: =AK41+IF(AK$3=Assumptions!$B$57,Assumptions!$B$56,0)-AK43 -> -5.4569682e-11
A45: EBT (Pre-Tax Income) | B45: =B40-B42 -> -29142.5 | C45: =C40-C42 -> -34174.6 | D45: =D40-D42 -> -27578.342 | E45: =E40-E42 -> -30335.195 | F45: =F40-F42 -> -23426 | G45: =G40-G42 -> -23330.909 | H45: =H40-H42 -> -16029.331 | I45: =I40-I42 -> -8499.859 | ... AK45: =AK40-AK42 -> 376290.35
A46: Taxes | B46: =MAX(B45,0)*Assumptions!$B$5 -> 0 | C46: =MAX(C45,0)*Assumptions!$B$5 -> 0 | D46: =MAX(D45,0)*Assumptions!$B$5 -> 0 | E46: =MAX(E45,0)*Assumptions!$B$5 -> 0 | F46: =MAX(F45,0)*Assumptions!$B$5 -> 0 | G46: =MAX(G45,0)*Assumptions!$B$5 -> 0 | H46: =MAX(H45,0)*Assumptions!$B$5 -> 0 | I46: =MAX(I45,0)*Assumptions!$B$5 -> 0 | ... AK46: =MAX(AK45,0)*Assumptions!$B$5 -> 79020.973
...

Sheet Annual
A1: Annual Summary - Years 1-5
A2: Years 1-3 aggregate the 36-month detail on the Monthly tab. Years 4-5 extrapolate from the Year-3 run-rate using the growth assumptions on the Assumptions tab.
B3: Year 1 | C3: Year 2 | D3: Year 3 | E3: Year 4 | F3: Year 5
A5: INCOME STATEMENT
A6: Total Revenue | B6: =SUM(Monthly!B15:M15) -> 971802.88 | C6: =SUM(Monthly!N15:Y15) -> 3381451.1 | D6: =SUM(Monthly!Z15:AK15) -> 7600756.9 | E6: =D6*(1+Assumptions!$B$62) -> 11781173 | F6: =E6*(1+Assumptions!$B$63) -> 16493643
A7: Total COGS | B7: =SUM(Monthly!B20:M20) -> 182840.52 | C7: =SUM(Monthly!N20:Y20) -> 633351.97 | D7: =SUM(Monthly!Z20:AK20) -> 1417790.2 | E7: =E6*($D$7/$D$6) -> 2197574.8 | F7: =F6*($D$7/$D$6) -> 3076604.7
A8: Gross Profit | B8: =B6-B7 -> 788962.36 | C8: =C6-C7 -> 2748099.1 | D8: =D6-D7 -> 6182966.8 | E8: =E6-E7 -> 9583598.5 | F8: =F6-F7 -> 13417038
A9: Gross Margin % | B9: =IFERROR(B8/B6,0) -> 0.81185432 | C9: =IFERROR(C8/C6,0) -> 0.81269817 | D9: =IFERROR(D8/D6,0) -> 0.81346724 | E9: =IFERROR(E8/E6,0) -> 0.81346724 | F9: =IFERROR(F8/F6,0) -> 0.81346724
A10: Total Operating Expenses | B10: =SUM(Monthly!B31:M31) -> 992950.72 | C10: =SUM(Monthly!N31:Y31) -> 2052362.8 | D10: =SUM(Monthly!Z31:AK31) -> 3238189.2 | E10: =E6*($D$10/$D$6) -> 5019193.3 | F10: =F6*($D$10/$D$6) -> 7026870.6
A11: EBITDA | B11: =B8-B10 -> -203988.36 | C11: =C8-C10 -> 695736.36 | D11: =D8-D10 -> 2944777.5 | E11: =E8-E10 -> 4564405.2 | F11: =F8-F10 -> 6390167.3
A12: Depreciation & Amortization | B12: =SUM(Monthly!B37:M37) -> 4875 | C12: =SUM(Monthly!N37:Y37) -> 13875 | D12: =SUM(Monthly!Z37:AK37) -> 22875 | E12: =D12*(1+Assumptions!$B$62) -> 35456.25 | F12: =E12*(1+Assumptions!$B$63) -> 49638.75
A13: EBIT | B13: =B11-B12 -> -208863.36 | C13: =C11-C12 -> 681861.36 | D13: =D11-D12 -> 2921902.5 | E13: =E11-E12 -> 4528948.9 | F13: =F11-F12 -> 6340528.5
A14: Interest Expense | B14: =SUM(Monthly!B42:M42) -> 0 | C14: =SUM(Monthly!N42:Y42) -> 12375 | D14: =SUM(Monthly!Z42:AK42) -> 4875 | E14: =D28*Assumptions!$B$58 -> -4.9112714e-12 | F14: =E28*Assumptions!$B$58 -> -4.9112714e-12
A15: EBT (Pre-Tax Income) | B15: =B13-B14 -> -208863.36 | C15: =C13-C14 -> 669486.36 | D15: =D13-D14 -> 2917027.5 | E15: =E13-E14 -> 4528948.9 | F15: =F13-F14 -> 6340528.5
A16: Taxes | B16: =SUM(Monthly!B46:M46) -> 915.01695 | C16: =SUM(Monthly!N46:Y46) -> 140592.14 | D16: =SUM(Monthly!Z46:AK46) -> 612575.78 | E16: =MAX(E15,0)*Assumptions!$B$5 -> 951079.28 | F16: =MAX(F15,0)*Assumptions!$B$5 -> 1331511
A17: Net Income | B17: =B15-B16 -> -209778.37 | C17: =C15-C16 -> 528894.22 | D17: =D15-D16 -> 2304451.8 | E17: =E15-E16 -> 3577869.7 | F17: =F15-F16 -> 5009017.5
A18: Net Margin % | B18: =IFERROR(B17/B6,0) -> -0.21586515 | C18: =IFERROR(C17/C6,0) -> 0.15641043 | D18: =IFERROR(D17/D6,0) -> 0.30318714 | E18: =IFERROR(E17/E6,0) -> 0.30369383 | F18: =IFERROR(F17/F6,0) -> 0.30369383
A20: BALANCE SHEET (Year-End)
A21: Cash | B21: =Monthly!M68 -> 2109894.8 | C21: =Monthly!Y68 -> 2638137.7 | D21: =Monthly!AK68 -> 4684430.9 | E21: =E50 -> 8206967.5 | F21: =F50 -> 13064403
A22: Accounts Receivable | B22: =Monthly!M50 -> 157621.63 | C22: =Monthly!Y50 -> 408054.02 | D22: =Monthly!AK50 -> 869364.44 | E22: =(E6/12)*Assumptions!$B$49/30 -> 981764.44 | F22: =(F6/12)*Assumptions!$B$49/30 -> 1374470.2
A23: PP&E, Net | B23: =Monthly!M39 -> 31125 | C23: =Monthly!Y39 -> 53250 | D23: =Monthly!AK39 -> 66375 | E23: =D23-E41-E12 -> 86718.75 | F23: =E23-F41-F12 -> 115200
A24: Total Assets | B24: =B21+B22+B23 -> 2298641.4 | C24: =C21+C22+C23 -> 3099441.7 | D24: =D21+D22+D23 -> 5620170.3 | E24: =E21+E22+E23 -> 9275450.7 | F24: =F21+F22+F23 -> 14554074
A26: Accounts Payable | B26: =Monthly!M51 -> 29609.001 | C26: =Monthly!Y51 -> 76298.854 | D26: =Monthly!AK51 -> 161920.48 | E26: =(E7/12)*Assumptions!$B$50/30 -> 183131.23 | F26: =(F7/12)*Assumptions!$B$50/30 -> 256383.72
A27: Deferred Revenue | B27: =Monthly!M52 -> 78810.817 | C27: =Monthly!Y52 -> 204027.01 | D27: =Monthly!AK52 -> 434682.22 | E27: =(E6/12)*Assumptions!$B$51/30 -> 490882.22 | F27: =(F6/12)*Assumptions!$B$51/30 -> 687235.11
A28: Debt | B28: =Monthly!M44 -> 0 | C28: =Monthly!Y44 -> 100000 | D28: =Monthly!AK44 -> -5.4569682e-11 | E28: =D28+E46+E47 -> -5.4569682e-11 | F28: =E28+F46+F47 -> -5.4569682e-11
A29: Total Liabilities | B29: =B26+B27+B28 -> 108419.82 | C29: =C26+C27+C28 -> 380325.86 | D29: =D26+D27+D28 -> 596602.7 | E29: =E26+E27+E28 -> 674013.45 | F29: =F26+F27+F28 -> 943618.83
A31: Paid-In Capital | B31: =IF(Assumptions!$B$55<=12,Assumptions!$B$54,0) -> 2400000 | C31: =IF(Assumptions!$B$55<=24,Assumptions!$B$54,0) -> 2400000 | D31: =IF(Assumptions!$B$55<=36,Assumptions!$B$54,0) -> 2400000 | E31: =D31 -> 2400000 | F31: =E31 -> 2400000
A32: Retained Earnings | B32: =B17 -> -209778.37 | C32: =B32+C17 -> 319115.85 | D32: =C32+D17 -> 2623567.6 | E32: =D32+E17 -> 6201437.3 | F32: =E32+F17 -> 11210455
A33: Total Equity | B33: =B31+B32 -> 2190221.6 | C33: =C31+C32 -> 2719115.9 | D33: =D31+D32 -> 5023567.6 | E33: =E31+E32 -> 8601437.3 | F33: =F31+F32 -> 13610455
A35: Total Liabilities & Equity | B35: =B29+B33 -> 2298641.4 | C35: =C29+C33 -> 3099441.7 | D35: =D29+D33 -> 5620170.3 | E35: =E29+E33 -> 9275450.7 | F35: =F29+F33 -> 14554074
A36: Balance Check (Assets - Liab. & Equity) | B36: =B24-B35 -> 0 | C36: =C24-C35 -> 0 | D36: =D24-D35 -> 0 | E36: =E24-E35 -> 0 | F36: =F24-F35 -> 0
A38: CASH FLOW STATEMENT
A39: Net Income | B39: =B17 -> -209778.37 | C39: =C17 -> 528894.22 | D39: =D17 -> 2304451.8 | E39: =E17 -> 3577869.7 | F39: =F17 -> 5009017.5
A40: + Depreciation & Amortization | B40: =B12 -> 4875 | C40: =C12 -> 13875 | D40: =D12 -> 22875 | E40: =E12 -> 35456.25 | F40: =F12 -> 49638.75
A41: - Capex | B41: =-SUM(Monthly!B35:M35) -> -36000 | C41: =-SUM(Monthly!N35:Y35) -> -36000 | D41: =-SUM(Monthly!Z35:AK35) -> -36000 | E41: =D41*(1+Assumptions!$B$62) -> -55800 | F41: =E41*(1+Assumptions!$B$63) -> -78120
A42: Change in Accounts Receivable | B42: =-(B22-0) -> -157621.63 | C42: =-(C22-B22) -> -250432.38 | D42: =-(D22-C22) -> -461310.42 | E42: =-(E22-D22) -> -112400 | F42: =-(F22-E22) -> -392705.78
A43: Change in Accounts Payable | B43: =(B26-0) -> 29609.001 | C43: =(C26-B26) -> 46689.853 | D43: =(D26-C26) -> 85621.627 | E43: =(E26-D26) -> 21210.748 | F43: =(F26-E26) -> 73252.492
A44: Change in Deferred Revenue | B44: =(B27-0) -> 78810.817 | C44: =(C27-B27) -> 125216.19 | D44: =(D27-C27) -> 230655.21 | E44: =(E27-D27) -> 56199.999 | F44: =(F27-E27) -> 196352.89
A45: + Equity Raised | B45: =B31-0 -> 2400000 | C45: =C31-B31 -> 0 | D45: =D31-C31 -> 0 | E45: =E31-D31 -> 0 | F45: =F31-E31 -> 0
A46: + Loan Proceeds | B46: =SUM(Monthly!B64:M64) -> 0 | C46: =SUM(Monthly!N64:Y64) -> 200000 | D46: =SUM(Monthly!Z64:AK64) -> 0 | E46: =IF(AND(Assumptions!$B$57+Assumptions!$B$59-1>=37,Assumptions!$B$57<=48),Assumptions!$B$56,0) -> 0 | F46: =IF(AND(Assumptions!$B$57+Assumptions!$B$59-1>=49,Assumptions!$B$57<=60),Assumptions!$B$56,0) -> 0
...

Sheet Unit Economics
A1: Unit Economics
A2: CAC = marketing spend / new customers added. LTV = ARPU x gross margin % / monthly churn %. Blended figures weight the two revenue streams by their ending customer counts.
B3: Year 1 | C3: Year 2 | D3: Year 3
A5: CUSTOMER ACQUISITION COST
A6: Marketing Spend | B6: =SUM(Monthly!B29:M29) -> 242950.72 | C6: =SUM(Monthly!N29:Y29) -> 845362.78 | D6: =SUM(Monthly!Z29:AK29) -> 1900189.2
A7: New Customers Added | B7: =SUM(Monthly!B7:M7)+SUM(Monthly!B9:M9) -> 464.73584 | C7: =SUM(Monthly!N7:Y7)+SUM(Monthly!N9:Y9) -> 907.5917 | D7: =SUM(Monthly!Z7:AK7)+SUM(Monthly!Z9:AK9) -> 1776.7804
A8: CAC (Customer Acquisition Cost) | B8: =IFERROR(B6/B7,0) -> 522.77165 | C8: =IFERROR(C6/C7,0) -> 931.43511 | D8: =IFERROR(D6/D7,0) -> 1069.4565
A10: LIFETIME VALUE
A11: Average Customers (period) | B11: =AVERAGE(Monthly!B8:M8)+AVERAGE(Monthly!B10:M10) -> 195.47402 | C11: =AVERAGE(Monthly!N8:Y8)+AVERAGE(Monthly!N10:Y10) -> 668.08638 | D11: =AVERAGE(Monthly!Z8:AK8)+AVERAGE(Monthly!Z10:AK10) -> 1476.9681
A12: ARPU, Monthly (blended) | B12: =(Annual!B6/12)/B11 -> 414.29328 | C12: =(Annual!C6/12)/C11 -> 421.78317 | D12: =(Annual!D6/12)/D11 -> 428.84908
A13: Blended Gross Margin % | B13: =Annual!B9 -> 0.81185432 | C13: =Annual!C9 -> 0.81269817 | D13: =Annual!D9 -> 0.81346724
A14: Blended Monthly Churn % | B14: =(Monthly!M8*Assumptions!$B$13+Monthly!M10*Assumptions!$B$21)/(Monthly!M8+Monthly!M10) -> 0.043895326 | C14: =(Monthly!Y8*Assumptions!$B$13+Monthly!Y10*Assumptions!$B$21)/(Monthly!Y8+Monthly!Y10) -> 0.043530112 | D14: =(Monthly!AK8*Assumptions!$B$13+Monthly!AK10*Assumptions!$B$21)/(Monthly!AK8+Monthly!AK10) -> 0.043211307
A15: LTV (Lifetime Value) | B15: =B12*B13/B14 -> 7662.451 | C15: =C12*C13/C14 -> 7874.6043 | D15: =D12*D13/D14 -> 8073.2266
A17: PAYBACK & RATIO
A18: LTV : CAC Ratio | B18: =IFERROR(B15/B8,0) -> 14.657358 | C18: =IFERROR(C15/C8,0) -> 8.4542705 | D18: =IFERROR(D15/D8,0) -> 7.5489064
A19: CAC Payback (months) | B19: =IFERROR(B8/(B12*B13),0) -> 1.5542685 | C19: =IFERROR(C8/(C12*C13),0) -> 2.717278 | D19: =IFERROR(D8/(D12*D13),0) -> 3.0656217

Sheet Runway & Raise
A1: Runway & Raise
A3: CURRENT POSITION & RUNWAY
A4: Latest Ending Cash (Month 36) | B4: =Monthly!AK68 -> 4684430.9
A5: Trailing 3-Month Average Monthly Burn | B5: =-AVERAGE(Monthly!AI66:AK66) -> -250613
A6: Months of Runway at Current Burn | B6: =IF(B5<=0,"Cash-flow positive",B4/B5) -> Cash-flow positive
A7: Cash-Out Month (within 36-Month Model) | B7: =IF(MIN(B47:AK47)=0,"Never within 36 months",MIN(B47:AK47)) -> Never within 36 months
A9: RAISE SIZING
A10: Months of Runway Desired | B10: 18
A11: Implied Additional Raise Needed | B11: =MAX(0,B10*B5-B4) -> 0
A13: YEAR-3 REVENUE SENSITIVITY: NEW-CUSTOMER GROWTH % vs CHURN %
A14: Note - simplified closed-form (not Excel Data Table): both streams' new-customer growth and churn are overridden with the single growth/churn pair shown for the grid cell, compounded for 36 months from each stream's Month-1 new-customer count, then annualized at the Month-36 run rate. Revenue = 12 x SUM over streams of [Month-1 New Customers x (1-churn)^35 x SUM_{k=1..36}((1+growth)/(1-churn))^(k-1) x Price]. Because the override is uniform across both streams, this will not exactly equal the base-case Year-3 figure on the Annual tab, which uses each stream's own growth/churn assumption.
B15: Churn % (rows) \ New-Customer Growth % (columns) ->
C16: 0.02 | D16: 0.04 | E16: 0.06 | F16: 0.08 | G16: 0.1
B17: 0.02 | C17: =12*(Assumptions!$B$11*(1-$B17)^35*IF(((1+C$16)/(1-$B17))=1,36,(((1+C$16)/(1-$B17))^36-1)/(((1+C$16)/(1-$B17))-1))*Assumptions!$B$14+Assumptions!$B$19*(1-$B17)^35*IF(((1+C$16)/(1-$B17))=1,36,(((1+C$16)/(1-$B17))^36-1)/(((1+C$16)/(1-$B17))-1))*Assumptions!$B$22) -> 5342505.9 | D17: =12*(Assumptions!$B$11*(1-$B17)^35*IF(((1+D$16)/(1-$B17))=1,36,(((1+D$16)/(1-$B17))^36-1)/(((1+D$16)/(1-$B17))-1))*Assumptions!$B$14+Assumptions!$B$19*(1-$B17)^35*IF(((1+D$16)/(1-$B17))=1,36,(((1+D$16)/(1-$B17))^36-1)/(((1+D$16)/(1-$B17))-1))*Assumptions!$B$22) -> 8284206 | E17: =12*(Assumptions!$B$11*(1-$B17)^35*IF(((1+E$16)/(1-$B17))=1,36,(((1+E$16)/(1-$B17))^36-1)/(((1+E$16)/(1-$B17))-1))*Assumptions!$B$14+Assumptions!$B$19*(1-$B17)^35*IF(((1+E$16)/(1-$B17))=1,36,(((1+E$16)/(1-$B17))^36-1)/(((1+E$16)/(1-$B17))-1))*Assumptions!$B$22) -> 13151491 | F17: =12*(Assumptions!$B$11*(1-$B17)^35*IF(((1+F$16)/(1-$B17))=1,36,(((1+F$16)/(1-$B17))^36-1)/(((1+F$16)/(1-$B17))-1))*Assumptions!$B$14+Assumptions!$B$19*(1-$B17)^35*IF(((1+F$16)/(1-$B17))=1,36,(((1+F$16)/(1-$B17))^36-1)/(((1+F$16)/(1-$B17))-1))*Assumptions!$B$22) -> 21257751 | G17: =12*(Assumptions!$B$11*(1-$B17)^35*IF(((1+G$16)/(1-$B17))=1,36,(((1+G$16)/(1-$B17))^36-1)/(((1+G$16)/(1-$B17))-1))*Assumptions!$B$14+Assumptions!$B$19*(1-$B17)^35*IF(((1+G$16)/(1-$B17))=1,36,(((1+G$16)/(1-$B17))^36-1)/(((1+G$16)/(1-$B17))-1))*Assumptions!$B$22) -> 34811311
B18: 0.035 | C18: =12*(Assumptions!$B$11*(1-$B18)^35*IF(((1+C$16)/(1-$B18))=1,36,(((1+C$16)/(1-$B18))^36-1)/(((1+C$16)/(1-$B18))-1))*Assumptions!$B$14+Assumptions!$B$19*(1-$B18)^35*IF(((1+C$16)/(1-$B18))=1,36,(((1+C$16)/(1-$B18))^36-1)/(((1+C$16)/(1-$B18))-1))*Assumptions!$B$22) -> 4399364.8 | D18: =12*(Assumptions!$B$11*(1-$B18)^35*IF(((1+D$16)/(1-$B18))=1,36,(((1+D$16)/(1-$B18))^36-1)/(((1+D$16)/(1-$B18))-1))*Assumptions!$B$14+Assumptions!$B$19*(1-$B18)^35*IF(((1+D$16)/(1-$B18))=1,36,(((1+D$16)/(1-$B18))^36-1)/(((1+D$16)/(1-$B18))-1))*Assumptions!$B$22) -> 7004229.2 | E18: =12*(Assumptions!$B$11*(1-$B18)^35*IF(((1+E$16)/(1-$B18))=1,36,(((1+E$16)/(1-$B18))^36-1)/(((1+E$16)/(1-$B18))-1))*Assumptions!$B$14+Assumptions!$B$19*(1-$B18)^35*IF(((1+E$16)/(1-$B18))=1,36,(((1+E$16)/(1-$B18))^36-1)/(((1+E$16)/(1-$B18))-1))*Assumptions!$B$22) -> 11372464 | F18: =12*(Assumptions!$B$11*(1-$B18)^35*IF(((1+F$16)/(1-$B18))=1,36,(((1+F$16)/(1-$B18))^36-1)/(((1+F$16)/(1-$B18))-1))*Assumptions!$B$14+Assumptions!$B$19*(1-$B18)^35*IF(((1+F$16)/(1-$B18))=1,36,(((1+F$16)/(1-$B18))^36-1)/(((1+F$16)/(1-$B18))-1))*Assumptions!$B$22) -> 18730782 | G18: =12*(Assumptions!$B$11*(1-$B18)^35*IF(((1+G$16)/(1-$B18))=1,36,(((1+G$16)/(1-$B18))^36-1)/(((1+G$16)/(1-$B18))-1))*Assumptions!$B$14+Assumptions!$B$19*(1-$B18)^35*IF(((1+G$16)/(1-$B18))=1,36,(((1+G$16)/(1-$B18))^36-1)/(((1+G$16)/(1-$B18))-1))*Assumptions!$B$22) -> 31152756
B19: 0.05 | C19: =12*(Assumptions!$B$11*(1-$B19)^35*IF(((1+C$16)/(1-$B19))=1,36,(((1+C$16)/(1-$B19))^36-1)/(((1+C$16)/(1-$B19))-1))*Assumptions!$B$14+Assumptions!$B$19*(1-$B19)^35*IF(((1+C$16)/(1-$B19))=1,36,(((1+C$16)/(1-$B19))^36-1)/(((1+C$16)/(1-$B19))-1))*Assumptions!$B$22) -> 3691082.9 | D19: =12*(Assumptions!$B$11*(1-$B19)^35*IF(((1+D$16)/(1-$B19))=1,36,(((1+D$16)/(1-$B19))^36-1)/(((1+D$16)/(1-$B19))-1))*Assumptions!$B$14+Assumptions!$B$19*(1-$B19)^35*IF(((1+D$16)/(1-$B19))=1,36,(((1+D$16)/(1-$B19))^36-1)/(((1+D$16)/(1-$B19))-1))*Assumptions!$B$22) -> 6019199.2 | E19: =12*(Assumptions!$B$11*(1-$B19)^35*IF(((1+E$16)/(1-$B19))=1,36,(((1+E$16)/(1-$B19))^36-1)/(((1+E$16)/(1-$B19))-1))*Assumptions!$B$14+Assumptions!$B$19*(1-$B19)^35*IF(((1+E$16)/(1-$B19))=1,36,(((1+E$16)/(1-$B19))^36-1)/(((1+E$16)/(1-$B19))-1))*Assumptions!$B$22) -> 9970862 | F19: =12*(Assumptions!$B$11*(1-$B19)^35*IF(((1+F$16)/(1-$B19))=1,36,(((1+F$16)/(1-$B19))^36-1)/(((1+F$16)/(1-$B19))-1))*Assumptions!$B$14+Assumptions!$B$19*(1-$B19)^35*IF(((1+F$16)/(1-$B19))=1,36,(((1+F$16)/(1-$B19))^36-1)/(((1+F$16)/(1-$B19))-1))*Assumptions!$B$22) -> 16695775 | G19: =12*(Assumptions!$B$11*(1-$B19)^35*IF(((1+G$16)/(1-$B19))=1,36,(((1+G$16)/(1-$B19))^36-1)/(((1+G$16)/(1-$B19))-1))*Assumptions!$B$14+Assumptions!$B$19*(1-$B19)^35*IF(((1+G$16)/(1-$B19))=1,36,(((1+G$16)/(1-$B19))^36-1)/(((1+G$16)/(1-$B19))-1))*Assumptions!$B$22) -> 28146886
B20: 0.065 | C20: =12*(Assumptions!$B$11*(1-$B20)^35*IF(((1+C$16)/(1-$B20))=1,36,(((1+C$16)/(1-$B20))^36-1)/(((1+C$16)/(1-$B20))-1))*Assumptions!$B$14+Assumptions!$B$19*(1-$B20)^35*IF(((1+C$16)/(1-$B20))=1,36,(((1+C$16)/(1-$B20))^36-1)/(((1+C$16)/(1-$B20))-1))*Assumptions!$B$22) -> 3150854.7 | D20: =12*(Assumptions!$B$11*(1-$B20)^35*IF(((1+D$16)/(1-$B20))=1,36,(((1+D$16)/(1-$B20))^36-1)/(((1+D$16)/(1-$B20))-1))*Assumptions!$B$14+Assumptions!$B$19*(1-$B20)^35*IF(((1+D$16)/(1-$B20))=1,36,(((1+D$16)/(1-$B20))^36-1)/(((1+D$16)/(1-$B20))-1))*Assumptions!$B$22) -> 5249283.6 | E20: =12*(Assumptions!$B$11*(1-$B20)^35*IF(((1+E$16)/(1-$B20))=1,36,(((1+E$16)/(1-$B20))^36-1)/(((1+E$16)/(1-$B20))-1))*Assumptions!$B$14+Assumptions!$B$19*(1-$B20)^35*IF(((1+E$16)/(1-$B20))=1,36,(((1+E$16)/(1-$B20))^36-1)/(((1+E$16)/(1-$B20))-1))*Assumptions!$B$22) -> 8849933.4 | F20: =12*(Assumptions!$B$11*(1-$B20)^35*IF(((1+F$16)/(1-$B20))=1,36,(((1+F$16)/(1-$B20))^36-1)/(((1+F$16)/(1-$B20))-1))*Assumptions!$B$14+Assumptions!$B$19*(1-$B20)^35*IF(((1+F$16)/(1-$B20))=1,36,(((1+F$16)/(1-$B20))^36-1)/(((1+F$16)/(1-$B20))-1))*Assumptions!$B$22) -> 15033776 | G20: =12*(Assumptions!$B$11*(1-$B20)^35*IF(((1+G$16)/(1-$B20))=1,36,(((1+G$16)/(1-$B20))^36-1)/(((1+G$16)/(1-$B20))-1))*Assumptions!$B$14+Assumptions!$B$19*(1-$B20)^35*IF(((1+G$16)/(1-$B20))=1,36,(((1+G$16)/(1-$B20))^36-1)/(((1+G$16)/(1-$B20))-1))*Assumptions!$B$22) -> 25645332
B21: 0.08 | C21: =12*(Assumptions!$B$11*(1-$B21)^35*IF(((1+C$16)/(1-$B21))=1,36,(((1+C$16)/(1-$B21))^36-1)/(((1+C$16)/(1-$B21))-1))*Assumptions!$B$14+Assumptions!$B$19*(1-$B21)^35*IF(((1+C$16)/(1-$B21))=1,36,(((1+C$16)/(1-$B21))^36-1)/(((1+C$16)/(1-$B21))-1))*Assumptions!$B$22) -> 2732128.3 | D21: =12*(Assumptions!$B$11*(1-$B21)^35*IF(((1+D$16)/(1-$B21))=1,36,(((1+D$16)/(1-$B21))^36-1)/(((1+D$16)/(1-$B21))-1))*Assumptions!$B$14+Assumptions!$B$19*(1-$B21)^35*IF(((1+D$16)/(1-$B21))=1,36,(((1+D$16)/(1-$B21))^36-1)/(((1+D$16)/(1-$B21))-1))*Assumptions!$B$22) -> 4638041.3 | E21: =12*(Assumptions!$B$11*(1-$B21)^35*IF(((1+E$16)/(1-$B21))=1,36,(((1+E$16)/(1-$B21))^36-1)/(((1+E$16)/(1-$B21))-1))*Assumptions!$B$14+Assumptions!$B$19*(1-$B21)^35*IF(((1+E$16)/(1-$B21))=1,36,(((1+E$16)/(1-$B21))^36-1)/(((1+E$16)/(1-$B21))-1))*Assumptions!$B$22) -> 7940227.5 | F21: =12*(Assumptions!$B$11*(1-$B21)^35*IF(((1+F$16)/(1-$B21))=1,36,(((1+F$16)/(1-$B21))^36-1)/(((1+F$16)/(1-$B21))-1))*Assumptions!$B$14+Assumptions!$B$19*(1-$B21)^35*IF(((1+F$16)/(1-$B21))=1,36,(((1+F$16)/(1-$B21))^36-1)/(((1+F$16)/(1-$B21))-1))*Assumptions!$B$22) -> 13658048 | G21: =12*(Assumptions!$B$11*(1-$B21)^35*IF(((1+G$16)/(1-$B21))=1,36,(((1+G$16)/(1-$B21))^36-1)/(((1+G$16)/(1-$B21))-1))*Assumptions!$B$14+Assumptions!$B$19*(1-$B21)^35*IF(((1+G$16)/(1-$B21))=1,36,(((1+G$16)/(1-$B21))^36-1)/(((1+G$16)/(1-$B21))-1))*Assumptions!$B$22) -> 23538166
A23: Base Case Year-3 Revenue (from Annual tab, for reference) | B23: =Annual!D6 -> 7600756.9
A45: SUPPORTING CALCULATION - CASH-OUT MONTH DETECTION (not a primary output)
A46: Month # | B46: =Monthly!B3 -> 1 | C46: =Monthly!C3 -> 2 | D46: =Monthly!D3 -> 3 | E46: =Monthly!E3 -> 4 | F46: =Monthly!F3 -> 5 | G46: =Monthly!G3 -> 6 | H46: =Monthly!H3 -> 7 | I46: =Monthly!I3 -> 8 | ... AK46: =Monthly!AK3 -> 36
A47: Month if Ending Cash < 0, else blank | B47: =IF(Monthly!B68<0,Monthly!B3,"") | C47: =IF(Monthly!C68<0,Monthly!C3,"") | D47: =IF(Monthly!D68<0,Monthly!D3,"") | E47: =IF(Monthly!E68<0,Monthly!E3,"") | F47: =IF(Monthly!F68<0,Monthly!F3,"") | G47: =IF(Monthly!G68<0,Monthly!G3,"") | H47: =IF(Monthly!H68<0,Monthly!H3,"") | I47: =IF(Monthly!I68<0,Monthly!I3,"") | ... AK47: =IF(Monthly!AK68<0,Monthly!AK3,"")

Sheet Charts
A1: Charts
A3: 1. Revenue by Stream - Monthly (stacked column)
A21: 2. Ending Cash - 36 Months (line)
A39: 3. Headcount Over Time (column)
A57: 4. Annual Revenue & Net Income - Years 1-5 (bonus, clustered column)
