Workbook

Sheet README
A1: Numbersmith - DCF Valuation Model
B3: Purpose
B4: This workbook builds a full discounted cash flow valuation for a public company: a WACC build (CAPM plus size premium), a five-year unlevered free cash flow forecast, a terminal value under both the Gordon growth and exit multiple methods, a bridge from enterprise value to implied share price, and two formula-driven sensitivity tables. Replace the sample company with your own company's data on the Inputs tab and every other tab recalculates automatically.
B9: How to use this model (6 steps)
B10: 1. Open the Inputs tab. Every blue cell is an editable input; every black or green cell is a formula and should not be overwritten.
B11: 2. Enter company name, ticker, valuation date, currency and units, then the three historical years of financials.
B12: 3. Enter five years of projection assumptions (revenue growth, EBITDA margin, D&A, capex and NWC, each as a percent of revenue).
B13: 4. Enter the WACC inputs (risk-free rate, equity risk premium, beta, size premium, cost of debt, tax rate, market cap, total debt).
B14: 5. Choose the terminal value method (1 = Gordon growth, 2 = exit multiple) and the mid-year convention toggle (1 = on, 0 = off).
B15: 6. Read the implied share price on the DCF tab, then stress-test it on the Sensitivity tab and review the Charts tab.
B17: Color legend
B18: Blue font | C18: Input - type over this. Nothing else on the model needs to change.
B19: Black font | C19: Formula - calculated on this sheet. Do not overwrite.
B20: Green font | C20: Cross-sheet link - pulled directly from another tab.
B22: Where to find each input
B23: Revenue, EBITDA, D&A, capex, change in NWC, tax rate (historical) | E23: Company 10-K / 10-Q - income statement, cash flow statement
B25: Diluted shares outstanding, current share price | E25: 10-K cover page (shares) and Yahoo Finance / any live quote (price)
B27: Market capitalization, total debt | E27: Yahoo Finance "Statistics" tab; total debt from the 10-K balance sheet
B29: Risk-free rate | E29: Current 10-year Treasury yield (Yahoo Finance ^TNX, or Treasury.gov)
B31: Equity risk premium, size premium | E31: Damodaran Online (pages.stern.nyu.edu/~adamodar/) - ERP and size premium data sets
B33: Beta | E33: Yahoo Finance "Statistics" tab, or regress the stock against the S&P 500
B35: Pre-tax cost of debt | E35: 10-K debt footnote (weighted average interest rate), or company bond yields
B37: Cash, minority interest, preferred stock, non-operating assets | E37: Most recent 10-K / 10-Q balance sheet
B39: Terminal growth rate, exit multiple | E39: Long-run GDP growth as a ceiling for terminal growth; peer trading multiples for the exit multiple
B41: Built by Numbersmith with AI assistance. Formulas are open; nothing is hidden or locked.
B43: For education and planning only, not financial advice.

Sheet Inputs
A1: Inputs - all blue cells are editable
A3: Company & General Information
A4: Company name | B4: Sample Industrials Inc
A5: Ticker | B5: SMPL
A6: Valuation date | B6: 46022
A7: Reporting currency | B7: USD
A8: Units | B8: $ millions, except per-share data
A10: Historical Financials ($ millions)
A11: Fiscal year | C11: 2023 | D11: 2024 | E11: 2025
A12: Revenue | C12: 3850 | D12: 4020 | E12: 4200
A13: EBITDA | C13: 690 | D13: 740 | E13: 798
A14: D&A | C14: 154 | D14: 161 | E14: 168
A15: Capex | C15: 173 | D15: 181 | E15: 189
A16: Change in NWC | C16: 39 | D16: 40 | E16: 42
A17: Tax rate | C17: 0.24 | D17: 0.24 | E17: 0.24
A19: Projection Assumptions (5-year forecast, % of revenue unless noted)
A20: Fiscal year | C20: 2026 | D20: 2027 | E20: 2028 | F20: 2029 | G20: 2030
A21: Revenue growth % | C21: 0.05 | D21: 0.045 | E21: 0.04 | F21: 0.035 | G21: 0.03
A22: EBITDA margin % | C22: 0.192 | D22: 0.194 | E22: 0.196 | F22: 0.198 | G22: 0.2
A23: D&A % of revenue | C23: 0.04 | D23: 0.04 | E23: 0.04 | F23: 0.04 | G23: 0.04
A24: Capex % of revenue | C24: 0.043 | D24: 0.042 | E24: 0.041 | F24: 0.04 | G24: 0.04
A25: Change in NWC % of revenue | C25: 0.01 | D25: 0.01 | E25: 0.01 | F25: 0.01 | G25: 0.01
A27: Terminal Value Assumptions
A28: Terminal method selector (1 = Gordon growth, 2 = exit multiple) | B28: 1
A29: Terminal growth rate (Gordon) | B29: 0.025
A30: Exit EV/EBITDA multiple | B30: 9
A32: Discounting Convention
A33: Mid-year convention toggle (1 = on, 0 = off) | B33: 1
A35: WACC Inputs
A36: Risk-free rate | B36: 0.043
A37: Equity risk premium | B37: 0.055
A38: Beta | B38: 1.15
A39: Size premium | B39: 0.008
A40: Pre-tax cost of debt | B40: 0.058
A41: Tax rate (WACC / projections) | B41: 0.24
A42: Market capitalization | B42: 5200
A43: Total debt | B43: 1450
A45: Net Debt Bridge & Share Data
A46: Cash & equivalents | B46: 320
A47: Total debt (linked from WACC inputs) | B47: =B43 -> 1450
...

Sheet WACC
A1: WACC - weighted average cost of capital
A3: Cost of Equity (CAPM + Size Premium)
A4: Risk-free rate | B4: =Inputs!B36 -> 0.043
A5: Beta | B5: =Inputs!B38 -> 1.15
A6: Equity risk premium | B6: =Inputs!B37 -> 0.055
A7: Size premium | B7: =Inputs!B39 -> 0.008
A8: Cost of equity = Rf + (Beta x ERP) + size premium | B8: =B4+(B5*B6)+B7 -> 0.11425
A10: After-Tax Cost of Debt
A11: Pre-tax cost of debt | B11: =Inputs!B40 -> 0.058
A12: Tax rate | B12: =Inputs!B41 -> 0.24
A13: After-tax cost of debt = pre-tax cost x (1 - tax rate) | B13: =B11*(1-B12) -> 0.04408
A15: Capital Structure Weights (Market Values)
A16: Market capitalization (equity value) | B16: =Inputs!B42 -> 5200
A17: Total debt | B17: =Inputs!B43 -> 1450
A18: Total capital (equity + debt) | B18: =B16+B17 -> 6650
A19: Weight of equity | B19: =B16/B18 -> 0.78195489
A20: Weight of debt | B20: =B17/B18 -> 0.21804511
A22: WACC
A23: WACC = (We x Ke) + (Wd x Kd, after-tax) | B23: =(B19*B8)+(B20*B13) -> 0.098949774

Sheet DCF
A1: DCF - unlevered free cash flow & valuation
A3: Fiscal Year
C4: =Inputs!C11 -> 2023 | D4: =Inputs!D11 -> 2024 | E4: =Inputs!E11 -> 2025 | F4: =Inputs!C20 -> 2026 | G4: =Inputs!D20 -> 2027 | H4: =Inputs!E20 -> 2028 | I4: =Inputs!F20 -> 2029 | J4: =Inputs!G20 -> 2030
A5: Period | C5: Historical | D5: Historical | E5: Historical | F5: Projected | G5: Projected | H5: Projected | I5: Projected | J5: Projected
A7: Unlevered Free Cash Flow Build ($ millions)
A8: Revenue | C8: =Inputs!C12 -> 3850 | D8: =Inputs!D12 -> 4020 | E8: =Inputs!E12 -> 4200 | F8: =E8*(1+Inputs!C21) -> 4410 | G8: =F8*(1+Inputs!D21) -> 4608.45 | H8: =G8*(1+Inputs!E21) -> 4792.788 | I8: =H8*(1+Inputs!F21) -> 4960.5356 | J8: =I8*(1+Inputs!G21) -> 5109.3516
A9: EBITDA | C9: =Inputs!C13 -> 690 | D9: =Inputs!D13 -> 740 | E9: =Inputs!E13 -> 798 | F9: =F8*Inputs!C22 -> 846.72 | G9: =G8*Inputs!D22 -> 894.0393 | H9: =H8*Inputs!E22 -> 939.38645 | I9: =I8*Inputs!F22 -> 982.18604 | J9: =J8*Inputs!G22 -> 1021.8703
A10: EBIT (EBITDA less D&A) | C10: =C9-C13 -> 536 | D10: =D9-D13 -> 579 | E10: =E9-E13 -> 630 | F10: =F9-F13 -> 670.32 | G10: =G9-G13 -> 709.7013 | H10: =H9-H13 -> 747.67493 | I10: =I9-I13 -> 783.76462 | J10: =J9-J13 -> 817.49626
A11: Taxes on EBIT | C11: =C10*Inputs!C17 -> 128.64 | D11: =D10*Inputs!D17 -> 138.96 | E11: =E10*Inputs!E17 -> 151.2 | F11: =F10*Inputs!$B$41 -> 160.8768 | G11: =G10*Inputs!$B$41 -> 170.32831 | H11: =H10*Inputs!$B$41 -> 179.44198 | I11: =I10*Inputs!$B$41 -> 188.10351 | J11: =J10*Inputs!$B$41 -> 196.1991
A12: NOPAT | C12: =C10-C11 -> 407.36 | D12: =D10-D11 -> 440.04 | E12: =E10-E11 -> 478.8 | F12: =F10-F11 -> 509.4432 | G12: =G10-G11 -> 539.37299 | H12: =H10-H11 -> 568.23295 | I12: =I10-I11 -> 595.66111 | J12: =J10-J11 -> 621.29716
A13: (+) D&A | C13: =Inputs!C14 -> 154 | D13: =Inputs!D14 -> 161 | E13: =Inputs!E14 -> 168 | F13: =F8*Inputs!C23 -> 176.4 | G13: =G8*Inputs!D23 -> 184.338 | H13: =H8*Inputs!E23 -> 191.71152 | I13: =I8*Inputs!F23 -> 198.42142 | J13: =J8*Inputs!G23 -> 204.37407
A14: (-) Capex | C14: =Inputs!C15 -> 173 | D14: =Inputs!D15 -> 181 | E14: =Inputs!E15 -> 189 | F14: =F8*Inputs!C24 -> 189.63 | G14: =G8*Inputs!D24 -> 193.5549 | H14: =H8*Inputs!E24 -> 196.50431 | I14: =I8*Inputs!F24 -> 198.42142 | J14: =J8*Inputs!G24 -> 204.37407
A15: (-) Change in NWC | C15: =Inputs!C16 -> 39 | D15: =Inputs!D16 -> 40 | E15: =Inputs!E16 -> 42 | F15: =F8*Inputs!C25 -> 44.1 | G15: =G8*Inputs!D25 -> 46.0845 | H15: =H8*Inputs!E25 -> 47.92788 | I15: =I8*Inputs!F25 -> 49.605356 | J15: =J8*Inputs!G25 -> 51.093516
A16: Unlevered FCF | C16: =C12+C13-C14-C15 -> 349.36 | D16: =D12+D13-D14-D15 -> 380.04 | E16: =E12+E13-E14-E15 -> 415.8 | F16: =F12+F13-F14-F15 -> 452.1132 | G16: =G12+G13-G14-G15 -> 484.07159 | H16: =H12+H13-H14-H15 -> 515.51228 | I16: =I12+I13-I14-I15 -> 546.05576 | J16: =J12+J13-J14-J15 -> 570.20364
A18: Discounting (honors mid-year convention toggle on Inputs)
A19: Year number (since last historical year) | F19: =F4-$E$4 -> 1 | G19: =G4-$E$4 -> 2 | H19: =H4-$E$4 -> 3 | I19: =I4-$E$4 -> 4 | J19: =J4-$E$4 -> 5
A20: Discount period | F20: =IF(Inputs!$B$33=1,F19-0.5,F19) -> 0.5 | G20: =IF(Inputs!$B$33=1,G19-0.5,G19) -> 1.5 | H20: =IF(Inputs!$B$33=1,H19-0.5,H19) -> 2.5 | I20: =IF(Inputs!$B$33=1,I19-0.5,I19) -> 3.5 | J20: =IF(Inputs!$B$33=1,J19-0.5,J19) -> 4.5
A21: Discount factor @ WACC | F21: =1/(1+WACC!$B$23)^F20 -> 0.95391807 | G21: =1/(1+WACC!$B$23)^G20 -> 0.868027 | H21: =1/(1+WACC!$B$23)^H20 -> 0.78986958 | I21: =1/(1+WACC!$B$23)^I20 -> 0.71874948 | J21: =1/(1+WACC!$B$23)^J20 -> 0.65403306
A22: PV of unlevered FCF | F22: =F16*F21 -> 431.27895 | G22: =G16*G21 -> 420.18721 | H22: =H16*H21 -> 407.18747 | I22: =I16*I21 -> 392.47729 | J22: =J16*J21 -> 372.93203
A24: Terminal Value
A25: Terminal value - Gordon growth method | D25: =J16*(1+Inputs!B29)/(WACC!$B$23-Inputs!B29) -> 7903.4553
A26: Terminal value - exit multiple method | D26: =J9*Inputs!B30 -> 9196.833
A27: Selected terminal value (per Inputs selector) | D27: =IF(Inputs!$B$28=1,D25,D26) -> 7903.4553
A28: PV of terminal value | D28: =D27*J21 -> 5169.121
A30: Enterprise Value to Implied Share Price Bridge
A31: Sum of PV of explicit FCFs (Yr 1-5) | D31: =SUM(F22:J22) -> 2024.063
A32: (+) PV of terminal value | D32: =D28 -> 5169.121
A33: Enterprise value | D33: =D31+D32 -> 7193.184
A34: (-) Total debt | D34: =-Inputs!B47 -> -1450
A35: (+) Cash & equivalents | D35: =Inputs!B46 -> 320
A36: (-) Minority interest | D36: =-Inputs!B48 -> -45
A37: (-) Preferred stock | D37: =-Inputs!B49 -> 0
A38: (+) Non-operating assets | D38: =Inputs!B50 -> 60
A39: Equity value | D39: =D33+D34+D35+D36+D37+D38 -> 6078.184
A40: Diluted shares outstanding (mm) | D40: =Inputs!B51 -> 140
A41: Implied share price | D41: =D39/D40 -> 43.4156
A42: Current share price | D42: =Inputs!B52 -> 37.14
A43: Upside / (downside) vs current price | D43: =D41/D42-1 -> 0.16897146
A44: Implied EV / LTM EBITDA | D44: =D33/E9 -> 9.014015

Sheet Sensitivity
A1: Sensitivity - implied share price grids (formula-built, not Data Table)
A3: Grid 1: Implied Share Price - WACC (rows) vs Terminal Growth Rate (columns), Gordon Growth Method
C4: WACC \ g | D4: =Inputs!$B$29-0.01 -> 0.015 | E4: =Inputs!$B$29-0.005 -> 0.02 | F4: =Inputs!$B$29 -> 0.025 | G4: =Inputs!$B$29+0.005 -> 0.03 | H4: =Inputs!$B$29+0.01 -> 0.035
C5: =WACC!$B$23-0.01 -> 0.088949774 | D5: =(SUMPRODUCT(DCF!$F$16:$J$16,1/(1+$C5)^DCF!$F$20:$J$20)+(DCF!$J$16*(1+D$4)/($C5-D$4))/(1+$C5)^DCF!$J$20-Inputs!$B$47+Inputs!$B$46-Inputs!$B$48-Inputs!$B$49+Inputs!$B$50)/Inputs!$B$51 -> 44.916538 | E5: =(SUMPRODUCT(DCF!$F$16:$J$16,1/(1+$C5)^DCF!$F$20:$J$20)+(DCF!$J$16*(1+E$4)/($C5-E$4))/(1+$C5)^DCF!$J$20-Inputs!$B$47+Inputs!$B$46-Inputs!$B$48-Inputs!$B$49+Inputs!$B$50)/Inputs!$B$51 -> 47.880514 | F5: =(SUMPRODUCT(DCF!$F$16:$J$16,1/(1+$C5)^DCF!$F$20:$J$20)+(DCF!$J$16*(1+F$4)/($C5-F$4))/(1+$C5)^DCF!$J$20-Inputs!$B$47+Inputs!$B$46-Inputs!$B$48-Inputs!$B$49+Inputs!$B$50)/Inputs!$B$51 -> 51.307976 | G5: =(SUMPRODUCT(DCF!$F$16:$J$16,1/(1+$C5)^DCF!$F$20:$J$20)+(DCF!$J$16*(1+G$4)/($C5-G$4))/(1+$C5)^DCF!$J$20-Inputs!$B$47+Inputs!$B$46-Inputs!$B$48-Inputs!$B$49+Inputs!$B$50)/Inputs!$B$51 -> 55.316859 | H5: =(SUMPRODUCT(DCF!$F$16:$J$16,1/(1+$C5)^DCF!$F$20:$J$20)+(DCF!$J$16*(1+H$4)/($C5-H$4))/(1+$C5)^DCF!$J$20-Inputs!$B$47+Inputs!$B$46-Inputs!$B$48-Inputs!$B$49+Inputs!$B$50)/Inputs!$B$51 -> 60.068818
C6: =WACC!$B$23-0.005 -> 0.093949774 | D6: =(SUMPRODUCT(DCF!$F$16:$J$16,1/(1+$C6)^DCF!$F$20:$J$20)+(DCF!$J$16*(1+D$4)/($C6-D$4))/(1+$C6)^DCF!$J$20-Inputs!$B$47+Inputs!$B$46-Inputs!$B$48-Inputs!$B$49+Inputs!$B$50)/Inputs!$B$51 -> 41.611193 | E6: =(SUMPRODUCT(DCF!$F$16:$J$16,1/(1+$C6)^DCF!$F$20:$J$20)+(DCF!$J$16*(1+E$4)/($C6-E$4))/(1+$C6)^DCF!$J$20-Inputs!$B$47+Inputs!$B$46-Inputs!$B$48-Inputs!$B$49+Inputs!$B$50)/Inputs!$B$51 -> 44.158571 | F6: =(SUMPRODUCT(DCF!$F$16:$J$16,1/(1+$C6)^DCF!$F$20:$J$20)+(DCF!$J$16*(1+F$4)/($C6-F$4))/(1+$C6)^DCF!$J$20-Inputs!$B$47+Inputs!$B$46-Inputs!$B$48-Inputs!$B$49+Inputs!$B$50)/Inputs!$B$51 -> 47.075403 | G6: =(SUMPRODUCT(DCF!$F$16:$J$16,1/(1+$C6)^DCF!$F$20:$J$20)+(DCF!$J$16*(1+G$4)/($C6-G$4))/(1+$C6)^DCF!$J$20-Inputs!$B$47+Inputs!$B$46-Inputs!$B$48-Inputs!$B$49+Inputs!$B$50)/Inputs!$B$51 -> 50.448348 | H6: =(SUMPRODUCT(DCF!$F$16:$J$16,1/(1+$C6)^DCF!$F$20:$J$20)+(DCF!$J$16*(1+H$4)/($C6-H$4))/(1+$C6)^DCF!$J$20-Inputs!$B$47+Inputs!$B$46-Inputs!$B$48-Inputs!$B$49+Inputs!$B$50)/Inputs!$B$51 -> 54.393466
C7: =WACC!$B$23 -> 0.098949774 | D7: =(SUMPRODUCT(DCF!$F$16:$J$16,1/(1+$C7)^DCF!$F$20:$J$20)+(DCF!$J$16*(1+D$4)/($C7-D$4))/(1+$C7)^DCF!$J$20-Inputs!$B$47+Inputs!$B$46-Inputs!$B$48-Inputs!$B$49+Inputs!$B$50)/Inputs!$B$51 -> 38.70015 | E7: =(SUMPRODUCT(DCF!$F$16:$J$16,1/(1+$C7)^DCF!$F$20:$J$20)+(DCF!$J$16*(1+E$4)/($C7-E$4))/(1+$C7)^DCF!$J$20-Inputs!$B$47+Inputs!$B$46-Inputs!$B$48-Inputs!$B$49+Inputs!$B$50)/Inputs!$B$51 -> 40.908557 | F7: =(SUMPRODUCT(DCF!$F$16:$J$16,1/(1+$C7)^DCF!$F$20:$J$20)+(DCF!$J$16*(1+F$4)/($C7-F$4))/(1+$C7)^DCF!$J$20-Inputs!$B$47+Inputs!$B$46-Inputs!$B$48-Inputs!$B$49+Inputs!$B$50)/Inputs!$B$51 -> 43.4156 | G7: =(SUMPRODUCT(DCF!$F$16:$J$16,1/(1+$C7)^DCF!$F$20:$J$20)+(DCF!$J$16*(1+G$4)/($C7-G$4))/(1+$C7)^DCF!$J$20-Inputs!$B$47+Inputs!$B$46-Inputs!$B$48-Inputs!$B$49+Inputs!$B$50)/Inputs!$B$51 -> 46.286247 | H7: =(SUMPRODUCT(DCF!$F$16:$J$16,1/(1+$C7)^DCF!$F$20:$J$20)+(DCF!$J$16*(1+H$4)/($C7-H$4))/(1+$C7)^DCF!$J$20-Inputs!$B$47+Inputs!$B$46-Inputs!$B$48-Inputs!$B$49+Inputs!$B$50)/Inputs!$B$51 -> 49.605785
C8: =WACC!$B$23+0.005 -> 0.10394977 | D8: =(SUMPRODUCT(DCF!$F$16:$J$16,1/(1+$C8)^DCF!$F$20:$J$20)+(DCF!$J$16*(1+D$4)/($C8-D$4))/(1+$C8)^DCF!$J$20-Inputs!$B$47+Inputs!$B$46-Inputs!$B$48-Inputs!$B$49+Inputs!$B$50)/Inputs!$B$51 -> 36.116902 | E8: =(SUMPRODUCT(DCF!$F$16:$J$16,1/(1+$C8)^DCF!$F$20:$J$20)+(DCF!$J$16*(1+E$4)/($C8-E$4))/(1+$C8)^DCF!$J$20-Inputs!$B$47+Inputs!$B$46-Inputs!$B$48-Inputs!$B$49+Inputs!$B$50)/Inputs!$B$51 -> 38.046136 | F8: =(SUMPRODUCT(DCF!$F$16:$J$16,1/(1+$C8)^DCF!$F$20:$J$20)+(DCF!$J$16*(1+F$4)/($C8-F$4))/(1+$C8)^DCF!$J$20-Inputs!$B$47+Inputs!$B$46-Inputs!$B$48-Inputs!$B$49+Inputs!$B$50)/Inputs!$B$51 -> 40.219732 | G8: =(SUMPRODUCT(DCF!$F$16:$J$16,1/(1+$C8)^DCF!$F$20:$J$20)+(DCF!$J$16*(1+G$4)/($C8-G$4))/(1+$C8)^DCF!$J$20-Inputs!$B$47+Inputs!$B$46-Inputs!$B$48-Inputs!$B$49+Inputs!$B$50)/Inputs!$B$51 -> 42.687258 | H8: =(SUMPRODUCT(DCF!$F$16:$J$16,1/(1+$C8)^DCF!$F$20:$J$20)+(DCF!$J$16*(1+H$4)/($C8-H$4))/(1+$C8)^DCF!$J$20-Inputs!$B$47+Inputs!$B$46-Inputs!$B$48-Inputs!$B$49+Inputs!$B$50)/Inputs!$B$51 -> 45.512656
C9: =WACC!$B$23+0.01 -> 0.10894977 | D9: =(SUMPRODUCT(DCF!$F$16:$J$16,1/(1+$C9)^DCF!$F$20:$J$20)+(DCF!$J$16*(1+D$4)/($C9-D$4))/(1+$C9)^DCF!$J$20-Inputs!$B$47+Inputs!$B$46-Inputs!$B$48-Inputs!$B$49+Inputs!$B$50)/Inputs!$B$51 -> 33.809099 | E9: =(SUMPRODUCT(DCF!$F$16:$J$16,1/(1+$C9)^DCF!$F$20:$J$20)+(DCF!$J$16*(1+E$4)/($C9-E$4))/(1+$C9)^DCF!$J$20-Inputs!$B$47+Inputs!$B$46-Inputs!$B$48-Inputs!$B$49+Inputs!$B$50)/Inputs!$B$51 -> 35.505934 | F9: =(SUMPRODUCT(DCF!$F$16:$J$16,1/(1+$C9)^DCF!$F$20:$J$20)+(DCF!$J$16*(1+F$4)/($C9-F$4))/(1+$C9)^DCF!$J$20-Inputs!$B$47+Inputs!$B$46-Inputs!$B$48-Inputs!$B$49+Inputs!$B$50)/Inputs!$B$51 -> 37.404895 | G9: =(SUMPRODUCT(DCF!$F$16:$J$16,1/(1+$C9)^DCF!$F$20:$J$20)+(DCF!$J$16*(1+G$4)/($C9-G$4))/(1+$C9)^DCF!$J$20-Inputs!$B$47+Inputs!$B$46-Inputs!$B$48-Inputs!$B$49+Inputs!$B$50)/Inputs!$B$51 -> 39.544384 | H9: =(SUMPRODUCT(DCF!$F$16:$J$16,1/(1+$C9)^DCF!$F$20:$J$20)+(DCF!$J$16*(1+H$4)/($C9-H$4))/(1+$C9)^DCF!$J$20-Inputs!$B$47+Inputs!$B$46-Inputs!$B$48-Inputs!$B$49+Inputs!$B$50)/Inputs!$B$51 -> 41.973189
A12: Grid 2: Implied Share Price - WACC (rows) vs Exit EV/EBITDA Multiple (columns)
C13: WACC \ multiple | D13: =Inputs!$B$30-2 -> 7 | E13: =Inputs!$B$30-1 -> 8 | F13: =Inputs!$B$30 -> 9 | G13: =Inputs!$B$30+1 -> 10 | H13: =Inputs!$B$30+2 -> 11
C14: =WACC!$B$23-0.01 -> 0.088949774 | D14: =(SUMPRODUCT(DCF!$F$16:$J$16,1/(1+$C14)^DCF!$F$20:$J$20)+(DCF!$J$9*D$13)/(1+$C14)^DCF!$J$20-Inputs!$B$47+Inputs!$B$46-Inputs!$B$48-Inputs!$B$49+Inputs!$B$50)/Inputs!$B$51 -> 41.639232 | E14: =(SUMPRODUCT(DCF!$F$16:$J$16,1/(1+$C14)^DCF!$F$20:$J$20)+(DCF!$J$9*E$13)/(1+$C14)^DCF!$J$20-Inputs!$B$47+Inputs!$B$46-Inputs!$B$48-Inputs!$B$49+Inputs!$B$50)/Inputs!$B$51 -> 46.613537 | F14: =(SUMPRODUCT(DCF!$F$16:$J$16,1/(1+$C14)^DCF!$F$20:$J$20)+(DCF!$J$9*F$13)/(1+$C14)^DCF!$J$20-Inputs!$B$47+Inputs!$B$46-Inputs!$B$48-Inputs!$B$49+Inputs!$B$50)/Inputs!$B$51 -> 51.587843 | G14: =(SUMPRODUCT(DCF!$F$16:$J$16,1/(1+$C14)^DCF!$F$20:$J$20)+(DCF!$J$9*G$13)/(1+$C14)^DCF!$J$20-Inputs!$B$47+Inputs!$B$46-Inputs!$B$48-Inputs!$B$49+Inputs!$B$50)/Inputs!$B$51 -> 56.562148 | H14: =(SUMPRODUCT(DCF!$F$16:$J$16,1/(1+$C14)^DCF!$F$20:$J$20)+(DCF!$J$9*H$13)/(1+$C14)^DCF!$J$20-Inputs!$B$47+Inputs!$B$46-Inputs!$B$48-Inputs!$B$49+Inputs!$B$50)/Inputs!$B$51 -> 61.536453
C15: =WACC!$B$23-0.005 -> 0.093949774 | D15: =(SUMPRODUCT(DCF!$F$16:$J$16,1/(1+$C15)^DCF!$F$20:$J$20)+(DCF!$J$9*D$13)/(1+$C15)^DCF!$J$20-Inputs!$B$47+Inputs!$B$46-Inputs!$B$48-Inputs!$B$49+Inputs!$B$50)/Inputs!$B$51 -> 40.764292 | E15: =(SUMPRODUCT(DCF!$F$16:$J$16,1/(1+$C15)^DCF!$F$20:$J$20)+(DCF!$J$9*E$13)/(1+$C15)^DCF!$J$20-Inputs!$B$47+Inputs!$B$46-Inputs!$B$48-Inputs!$B$49+Inputs!$B$50)/Inputs!$B$51 -> 45.637103 | F15: =(SUMPRODUCT(DCF!$F$16:$J$16,1/(1+$C15)^DCF!$F$20:$J$20)+(DCF!$J$9*F$13)/(1+$C15)^DCF!$J$20-Inputs!$B$47+Inputs!$B$46-Inputs!$B$48-Inputs!$B$49+Inputs!$B$50)/Inputs!$B$51 -> 50.509913 | G15: =(SUMPRODUCT(DCF!$F$16:$J$16,1/(1+$C15)^DCF!$F$20:$J$20)+(DCF!$J$9*G$13)/(1+$C15)^DCF!$J$20-Inputs!$B$47+Inputs!$B$46-Inputs!$B$48-Inputs!$B$49+Inputs!$B$50)/Inputs!$B$51 -> 55.382724 | H15: =(SUMPRODUCT(DCF!$F$16:$J$16,1/(1+$C15)^DCF!$F$20:$J$20)+(DCF!$J$9*H$13)/(1+$C15)^DCF!$J$20-Inputs!$B$47+Inputs!$B$46-Inputs!$B$48-Inputs!$B$49+Inputs!$B$50)/Inputs!$B$51 -> 60.255535
C16: =WACC!$B$23 -> 0.098949774 | D16: =(SUMPRODUCT(DCF!$F$16:$J$16,1/(1+$C16)^DCF!$F$20:$J$20)+(DCF!$J$9*D$13)/(1+$C16)^DCF!$J$20-Inputs!$B$47+Inputs!$B$46-Inputs!$B$48-Inputs!$B$49+Inputs!$B$50)/Inputs!$B$51 -> 39.910156 | E16: =(SUMPRODUCT(DCF!$F$16:$J$16,1/(1+$C16)^DCF!$F$20:$J$20)+(DCF!$J$9*E$13)/(1+$C16)^DCF!$J$20-Inputs!$B$47+Inputs!$B$46-Inputs!$B$48-Inputs!$B$49+Inputs!$B$50)/Inputs!$B$51 -> 44.683991 | F16: =(SUMPRODUCT(DCF!$F$16:$J$16,1/(1+$C16)^DCF!$F$20:$J$20)+(DCF!$J$9*F$13)/(1+$C16)^DCF!$J$20-Inputs!$B$47+Inputs!$B$46-Inputs!$B$48-Inputs!$B$49+Inputs!$B$50)/Inputs!$B$51 -> 49.457827 | G16: =(SUMPRODUCT(DCF!$F$16:$J$16,1/(1+$C16)^DCF!$F$20:$J$20)+(DCF!$J$9*G$13)/(1+$C16)^DCF!$J$20-Inputs!$B$47+Inputs!$B$46-Inputs!$B$48-Inputs!$B$49+Inputs!$B$50)/Inputs!$B$51 -> 54.231662 | H16: =(SUMPRODUCT(DCF!$F$16:$J$16,1/(1+$C16)^DCF!$F$20:$J$20)+(DCF!$J$9*H$13)/(1+$C16)^DCF!$J$20-Inputs!$B$47+Inputs!$B$46-Inputs!$B$48-Inputs!$B$49+Inputs!$B$50)/Inputs!$B$51 -> 59.005498
C17: =WACC!$B$23+0.005 -> 0.10394977 | D17: =(SUMPRODUCT(DCF!$F$16:$J$16,1/(1+$C17)^DCF!$F$20:$J$20)+(DCF!$J$9*D$13)/(1+$C17)^DCF!$J$20-Inputs!$B$47+Inputs!$B$46-Inputs!$B$48-Inputs!$B$49+Inputs!$B$50)/Inputs!$B$51 -> 39.076228 | E17: =(SUMPRODUCT(DCF!$F$16:$J$16,1/(1+$C17)^DCF!$F$20:$J$20)+(DCF!$J$9*E$13)/(1+$C17)^DCF!$J$20-Inputs!$B$47+Inputs!$B$46-Inputs!$B$48-Inputs!$B$49+Inputs!$B$50)/Inputs!$B$51 -> 43.753535 | F17: =(SUMPRODUCT(DCF!$F$16:$J$16,1/(1+$C17)^DCF!$F$20:$J$20)+(DCF!$J$9*F$13)/(1+$C17)^DCF!$J$20-Inputs!$B$47+Inputs!$B$46-Inputs!$B$48-Inputs!$B$49+Inputs!$B$50)/Inputs!$B$51 -> 48.430841 | G17: =(SUMPRODUCT(DCF!$F$16:$J$16,1/(1+$C17)^DCF!$F$20:$J$20)+(DCF!$J$9*G$13)/(1+$C17)^DCF!$J$20-Inputs!$B$47+Inputs!$B$46-Inputs!$B$48-Inputs!$B$49+Inputs!$B$50)/Inputs!$B$51 -> 53.108148 | H17: =(SUMPRODUCT(DCF!$F$16:$J$16,1/(1+$C17)^DCF!$F$20:$J$20)+(DCF!$J$9*H$13)/(1+$C17)^DCF!$J$20-Inputs!$B$47+Inputs!$B$46-Inputs!$B$48-Inputs!$B$49+Inputs!$B$50)/Inputs!$B$51 -> 57.785454
C18: =WACC!$B$23+0.01 -> 0.10894977 | D18: =(SUMPRODUCT(DCF!$F$16:$J$16,1/(1+$C18)^DCF!$F$20:$J$20)+(DCF!$J$9*D$13)/(1+$C18)^DCF!$J$20-Inputs!$B$47+Inputs!$B$46-Inputs!$B$48-Inputs!$B$49+Inputs!$B$50)/Inputs!$B$51 -> 38.261934 | E18: =(SUMPRODUCT(DCF!$F$16:$J$16,1/(1+$C18)^DCF!$F$20:$J$20)+(DCF!$J$9*E$13)/(1+$C18)^DCF!$J$20-Inputs!$B$47+Inputs!$B$46-Inputs!$B$48-Inputs!$B$49+Inputs!$B$50)/Inputs!$B$51 -> 42.845087 | F18: =(SUMPRODUCT(DCF!$F$16:$J$16,1/(1+$C18)^DCF!$F$20:$J$20)+(DCF!$J$9*F$13)/(1+$C18)^DCF!$J$20-Inputs!$B$47+Inputs!$B$46-Inputs!$B$48-Inputs!$B$49+Inputs!$B$50)/Inputs!$B$51 -> 47.428239 | G18: =(SUMPRODUCT(DCF!$F$16:$J$16,1/(1+$C18)^DCF!$F$20:$J$20)+(DCF!$J$9*G$13)/(1+$C18)^DCF!$J$20-Inputs!$B$47+Inputs!$B$46-Inputs!$B$48-Inputs!$B$49+Inputs!$B$50)/Inputs!$B$51 -> 52.011392 | H18: =(SUMPRODUCT(DCF!$F$16:$J$16,1/(1+$C18)^DCF!$F$20:$J$20)+(DCF!$J$9*H$13)/(1+$C18)^DCF!$J$20-Inputs!$B$47+Inputs!$B$46-Inputs!$B$48-Inputs!$B$49+Inputs!$B$50)/Inputs!$B$51 -> 56.594544
A20: Green shading = implied share price above the current share price on the Inputs tab.

Sheet Charts
A1: Charts
A3: Chart 1 data: unlevered FCF projection ($ millions)
A4: Fiscal year | B4: =DCF!F4 -> 2026 | C4: =DCF!G4 -> 2027 | D4: =DCF!H4 -> 2028 | E4: =DCF!I4 -> 2029 | F4: =DCF!J4 -> 2030
A5: Unlevered FCF | B5: =DCF!F16 -> 452.1132 | C5: =DCF!G16 -> 484.07159 | D5: =DCF!H16 -> 515.51228 | E5: =DCF!I16 -> 546.05576 | F5: =DCF!J16 -> 570.20364
A8: Chart 2 data: implied share price, min / base / max vs current
A9: Scenario | B9: Min | C9: Base | D9: Max | E9: Current
A10: Implied price | B10: =MIN(Sensitivity!D5:H9,Sensitivity!D14:H18) -> 33.809099 | C10: =DCF!D41 -> 43.4156 | D10: =MAX(Sensitivity!D5:H9,Sensitivity!D14:H18) -> 61.536453 | E10: =DCF!D42 -> 37.14
